[2025-04-01T10:44:36.216+0000] {local_task_job_runner.py:123} INFO - ::group::Pre task execution logs
[2025-04-01T10:44:36.298+0000] {taskinstance.py:2614} INFO - Dependencies all met for dep_context=non-requeueable deps ti=<TaskInstance: premier_league_ingestion.download_data_2022_23 scheduled__2025-03-23T00:00:00+00:00 [queued]>
[2025-04-01T10:44:36.432+0000] {taskinstance.py:2614} INFO - Dependencies all met for dep_context=requeueable deps ti=<TaskInstance: premier_league_ingestion.download_data_2022_23 scheduled__2025-03-23T00:00:00+00:00 [queued]>
[2025-04-01T10:44:36.435+0000] {taskinstance.py:2867} INFO - Starting attempt 2 of 2
[2025-04-01T10:44:36.534+0000] {taskinstance.py:2890} INFO - Executing <Task(PythonOperator): download_data_2022_23> on 2025-03-23 00:00:00+00:00
[2025-04-01T10:44:36.594+0000] {warnings.py:112} WARNING - /home/***/.local/lib/python3.12/site-packages/***/task/task_runner/standard_task_runner.py:70: DeprecationWarning: This process (pid=248) is multi-threaded, use of fork() may lead to deadlocks in the child.
  pid = os.fork()

[2025-04-01T10:44:36.619+0000] {standard_task_runner.py:72} INFO - Started process 257 to run task
[2025-04-01T10:44:36.602+0000] {standard_task_runner.py:104} INFO - Running: ['***', 'tasks', 'run', 'premier_league_ingestion', 'download_data_2022_23', 'scheduled__2025-03-23T00:00:00+00:00', '--job-id', '11', '--raw', '--subdir', 'DAGS_FOLDER/premier_league_dag.py', '--cfg-path', '/tmp/tmpa9rut38t']
[2025-04-01T10:44:36.625+0000] {standard_task_runner.py:105} INFO - Job 11: Subtask download_data_2022_23
[2025-04-01T10:44:36.846+0000] {task_command.py:467} INFO - Running <TaskInstance: premier_league_ingestion.download_data_2022_23 scheduled__2025-03-23T00:00:00+00:00 [running]> on host 6cd6fb1a2334
[2025-04-01T10:44:37.382+0000] {taskinstance.py:3134} INFO - Exporting env vars: AIRFLOW_CTX_DAG_OWNER='***' AIRFLOW_CTX_DAG_ID='premier_league_ingestion' AIRFLOW_CTX_TASK_ID='download_data_2022_23' AIRFLOW_CTX_EXECUTION_DATE='2025-03-23T00:00:00+00:00' AIRFLOW_CTX_TRY_NUMBER='2' AIRFLOW_CTX_DAG_RUN_ID='scheduled__2025-03-23T00:00:00+00:00'
[2025-04-01T10:44:37.386+0000] {taskinstance.py:732} INFO - ::endgroup::
[2025-04-01T10:44:37.530+0000] {taskinstance.py:3313} ERROR - Task failed with exception
Traceback (most recent call last):
  File "/home/airflow/.local/lib/python3.12/site-packages/airflow/models/taskinstance.py", line 768, in _execute_task
    result = _execute_callable(context=context, **execute_callable_kwargs)
             ^^^^^^^^^^^^^^^^^^^^^^^^^^^^^^^^^^^^^^^^^^^^^^^^^^^^^^^^^^^^^
  File "/home/airflow/.local/lib/python3.12/site-packages/airflow/models/taskinstance.py", line 734, in _execute_callable
    return ExecutionCallableRunner(
           ^^^^^^^^^^^^^^^^^^^^^^^^
  File "/home/airflow/.local/lib/python3.12/site-packages/airflow/utils/operator_helpers.py", line 252, in run
    return self.func(*args, **kwargs)
           ^^^^^^^^^^^^^^^^^^^^^^^^^^
  File "/home/airflow/.local/lib/python3.12/site-packages/airflow/models/baseoperator.py", line 424, in wrapper
    return func(self, *args, **kwargs)
           ^^^^^^^^^^^^^^^^^^^^^^^^^^^
  File "/home/airflow/.local/lib/python3.12/site-packages/airflow/operators/python.py", line 238, in execute
    return_value = self.execute_callable()
                   ^^^^^^^^^^^^^^^^^^^^^^^
  File "/home/airflow/.local/lib/python3.12/site-packages/airflow/operators/python.py", line 256, in execute_callable
    return runner.run(*self.op_args, **self.op_kwargs)
           ^^^^^^^^^^^^^^^^^^^^^^^^^^^^^^^^^^^^^^^^^^^
  File "/home/airflow/.local/lib/python3.12/site-packages/airflow/utils/operator_helpers.py", line 252, in run
    return self.func(*args, **kwargs)
           ^^^^^^^^^^^^^^^^^^^^^^^^^^
  File "/opt/airflow/dags/scripts/download_data.py", line 11, in download_data
    os.makedirs(data_dir, exist_ok=True)
  File "<frozen os>", line 225, in makedirs
PermissionError: [Errno 13] Permission denied: '../Data'
[2025-04-01T10:44:37.631+0000] {taskinstance.py:1226} INFO - Marking task as FAILED. dag_id=premier_league_ingestion, task_id=download_data_2022_23, run_id=scheduled__2025-03-23T00:00:00+00:00, execution_date=20250323T000000, start_date=20250401T104436, end_date=20250401T104437
[2025-04-01T10:44:37.795+0000] {taskinstance.py:341} INFO - ::group::Post task execution logs
[2025-04-01T10:44:37.801+0000] {standard_task_runner.py:124} ERROR - Failed to execute job 11 for task download_data_2022_23 ([Errno 13] Permission denied: '../Data'; 257)
Traceback (most recent call last):
  File "/home/airflow/.local/lib/python3.12/site-packages/airflow/task/task_runner/standard_task_runner.py", line 117, in _start_by_fork
    ret = args.func(args, dag=self.dag)
          ^^^^^^^^^^^^^^^^^^^^^^^^^^^^^
  File "/home/airflow/.local/lib/python3.12/site-packages/airflow/cli/cli_config.py", line 49, in command
    return func(*args, **kwargs)
           ^^^^^^^^^^^^^^^^^^^^^
  File "/home/airflow/.local/lib/python3.12/site-packages/airflow/utils/cli.py", line 116, in wrapper
    return f(*args, **kwargs)
           ^^^^^^^^^^^^^^^^^^
  File "/home/airflow/.local/lib/python3.12/site-packages/airflow/cli/commands/task_command.py", line 483, in task_run
    task_return_code = _run_task_by_selected_method(args, _dag, ti)
                       ^^^^^^^^^^^^^^^^^^^^^^^^^^^^^^^^^^^^^^^^^^^^
  File "/home/airflow/.local/lib/python3.12/site-packages/airflow/cli/commands/task_command.py", line 256, in _run_task_by_selected_method
    return _run_raw_task(args, ti)
           ^^^^^^^^^^^^^^^^^^^^^^^
  File "/home/airflow/.local/lib/python3.12/site-packages/airflow/cli/commands/task_command.py", line 341, in _run_raw_task
    return ti._run_raw_task(
           ^^^^^^^^^^^^^^^^^
  File "/home/airflow/.local/lib/python3.12/site-packages/airflow/utils/session.py", line 97, in wrapper
    return func(*args, session=session, **kwargs)
           ^^^^^^^^^^^^^^^^^^^^^^^^^^^^^^^^^^^^^^
  File "/home/airflow/.local/lib/python3.12/site-packages/airflow/models/taskinstance.py", line 3006, in _run_raw_task
    return _run_raw_task(
           ^^^^^^^^^^^^^^
  File "/home/airflow/.local/lib/python3.12/site-packages/airflow/models/taskinstance.py", line 274, in _run_raw_task
    TaskInstance._execute_task_with_callbacks(
  File "/home/airflow/.local/lib/python3.12/site-packages/airflow/models/taskinstance.py", line 3161, in _execute_task_with_callbacks
    result = self._execute_task(context, task_orig)
             ^^^^^^^^^^^^^^^^^^^^^^^^^^^^^^^^^^^^^^
  File "/home/airflow/.local/lib/python3.12/site-packages/airflow/models/taskinstance.py", line 3185, in _execute_task
    return _execute_task(self, context, task_orig)
           ^^^^^^^^^^^^^^^^^^^^^^^^^^^^^^^^^^^^^^^
  File "/home/airflow/.local/lib/python3.12/site-packages/airflow/models/taskinstance.py", line 768, in _execute_task
    result = _execute_callable(context=context, **execute_callable_kwargs)
             ^^^^^^^^^^^^^^^^^^^^^^^^^^^^^^^^^^^^^^^^^^^^^^^^^^^^^^^^^^^^^
  File "/home/airflow/.local/lib/python3.12/site-packages/airflow/models/taskinstance.py", line 734, in _execute_callable
    return ExecutionCallableRunner(
           ^^^^^^^^^^^^^^^^^^^^^^^^
  File "/home/airflow/.local/lib/python3.12/site-packages/airflow/utils/operator_helpers.py", line 252, in run
    return self.func(*args, **kwargs)
           ^^^^^^^^^^^^^^^^^^^^^^^^^^
  File "/home/airflow/.local/lib/python3.12/site-packages/airflow/models/baseoperator.py", line 424, in wrapper
    return func(self, *args, **kwargs)
           ^^^^^^^^^^^^^^^^^^^^^^^^^^^
  File "/home/airflow/.local/lib/python3.12/site-packages/airflow/operators/python.py", line 238, in execute
    return_value = self.execute_callable()
                   ^^^^^^^^^^^^^^^^^^^^^^^
  File "/home/airflow/.local/lib/python3.12/site-packages/airflow/operators/python.py", line 256, in execute_callable
    return runner.run(*self.op_args, **self.op_kwargs)
           ^^^^^^^^^^^^^^^^^^^^^^^^^^^^^^^^^^^^^^^^^^^
  File "/home/airflow/.local/lib/python3.12/site-packages/airflow/utils/operator_helpers.py", line 252, in run
    return self.func(*args, **kwargs)
           ^^^^^^^^^^^^^^^^^^^^^^^^^^
  File "/opt/airflow/dags/scripts/download_data.py", line 11, in download_data
    os.makedirs(data_dir, exist_ok=True)
  File "<frozen os>", line 225, in makedirs
PermissionError: [Errno 13] Permission denied: '../Data'
[2025-04-01T10:44:37.877+0000] {local_task_job_runner.py:266} INFO - Task exited with return code 1
[2025-04-01T10:44:38.104+0000] {taskinstance.py:3901} INFO - 0 downstream tasks scheduled from follow-on schedule check
[2025-04-01T10:44:38.130+0000] {local_task_job_runner.py:245} INFO - ::endgroup::
[2025-04-01T11:32:04.053+0000] {local_task_job_runner.py:123} INFO - ::group::Pre task execution logs
[2025-04-01T11:32:04.153+0000] {taskinstance.py:2614} INFO - Dependencies all met for dep_context=non-requeueable deps ti=<TaskInstance: premier_league_ingestion.download_data_2022_23 scheduled__2025-03-23T00:00:00+00:00 [queued]>
[2025-04-01T11:32:04.199+0000] {taskinstance.py:2614} INFO - Dependencies all met for dep_context=requeueable deps ti=<TaskInstance: premier_league_ingestion.download_data_2022_23 scheduled__2025-03-23T00:00:00+00:00 [queued]>
[2025-04-01T11:32:04.200+0000] {taskinstance.py:2867} INFO - Starting attempt 2 of 2
[2025-04-01T11:32:04.245+0000] {taskinstance.py:2890} INFO - Executing <Task(PythonOperator): download_data_2022_23> on 2025-03-23 00:00:00+00:00
[2025-04-01T11:32:04.279+0000] {warnings.py:112} WARNING - /home/***/.local/lib/python3.12/site-packages/***/task/task_runner/standard_task_runner.py:70: DeprecationWarning: This process (pid=513) is multi-threaded, use of fork() may lead to deadlocks in the child.
  pid = os.fork()

[2025-04-01T11:32:04.290+0000] {standard_task_runner.py:72} INFO - Started process 527 to run task
[2025-04-01T11:32:04.287+0000] {standard_task_runner.py:104} INFO - Running: ['***', 'tasks', 'run', 'premier_league_ingestion', 'download_data_2022_23', 'scheduled__2025-03-23T00:00:00+00:00', '--job-id', '16', '--raw', '--subdir', 'DAGS_FOLDER/premier_league_dag.py', '--cfg-path', '/tmp/tmpo6vbgrdw']
[2025-04-01T11:32:04.301+0000] {standard_task_runner.py:105} INFO - Job 16: Subtask download_data_2022_23
[2025-04-01T11:32:04.598+0000] {task_command.py:467} INFO - Running <TaskInstance: premier_league_ingestion.download_data_2022_23 scheduled__2025-03-23T00:00:00+00:00 [running]> on host 0366bde5a007
[2025-04-01T11:32:05.102+0000] {taskinstance.py:3134} INFO - Exporting env vars: AIRFLOW_CTX_DAG_OWNER='***' AIRFLOW_CTX_DAG_ID='premier_league_ingestion' AIRFLOW_CTX_TASK_ID='download_data_2022_23' AIRFLOW_CTX_EXECUTION_DATE='2025-03-23T00:00:00+00:00' AIRFLOW_CTX_TRY_NUMBER='2' AIRFLOW_CTX_DAG_RUN_ID='scheduled__2025-03-23T00:00:00+00:00'
[2025-04-01T11:32:05.108+0000] {taskinstance.py:732} INFO - ::endgroup::
[2025-04-01T11:32:05.159+0000] {taskinstance.py:3313} ERROR - Task failed with exception
Traceback (most recent call last):
  File "/home/airflow/.local/lib/python3.12/site-packages/airflow/models/taskinstance.py", line 768, in _execute_task
    result = _execute_callable(context=context, **execute_callable_kwargs)
             ^^^^^^^^^^^^^^^^^^^^^^^^^^^^^^^^^^^^^^^^^^^^^^^^^^^^^^^^^^^^^
  File "/home/airflow/.local/lib/python3.12/site-packages/airflow/models/taskinstance.py", line 734, in _execute_callable
    return ExecutionCallableRunner(
           ^^^^^^^^^^^^^^^^^^^^^^^^
  File "/home/airflow/.local/lib/python3.12/site-packages/airflow/utils/operator_helpers.py", line 252, in run
    return self.func(*args, **kwargs)
           ^^^^^^^^^^^^^^^^^^^^^^^^^^
  File "/home/airflow/.local/lib/python3.12/site-packages/airflow/models/baseoperator.py", line 424, in wrapper
    return func(self, *args, **kwargs)
           ^^^^^^^^^^^^^^^^^^^^^^^^^^^
  File "/home/airflow/.local/lib/python3.12/site-packages/airflow/operators/python.py", line 238, in execute
    return_value = self.execute_callable()
                   ^^^^^^^^^^^^^^^^^^^^^^^
  File "/home/airflow/.local/lib/python3.12/site-packages/airflow/operators/python.py", line 256, in execute_callable
    return runner.run(*self.op_args, **self.op_kwargs)
           ^^^^^^^^^^^^^^^^^^^^^^^^^^^^^^^^^^^^^^^^^^^
  File "/home/airflow/.local/lib/python3.12/site-packages/airflow/utils/operator_helpers.py", line 252, in run
    return self.func(*args, **kwargs)
           ^^^^^^^^^^^^^^^^^^^^^^^^^^
  File "/opt/airflow/dags/scripts/download_data.py", line 13, in download_data
    os.makedirs(data_dir, exist_ok=True)
  File "<frozen os>", line 225, in makedirs
PermissionError: [Errno 13] Permission denied: '../data'
[2025-04-01T11:32:05.219+0000] {taskinstance.py:1226} INFO - Marking task as FAILED. dag_id=premier_league_ingestion, task_id=download_data_2022_23, run_id=scheduled__2025-03-23T00:00:00+00:00, execution_date=20250323T000000, start_date=20250401T113204, end_date=20250401T113205
[2025-04-01T11:32:05.480+0000] {taskinstance.py:341} INFO - ::group::Post task execution logs
[2025-04-01T11:32:05.483+0000] {standard_task_runner.py:124} ERROR - Failed to execute job 16 for task download_data_2022_23 ([Errno 13] Permission denied: '../data'; 527)
Traceback (most recent call last):
  File "/home/airflow/.local/lib/python3.12/site-packages/airflow/task/task_runner/standard_task_runner.py", line 117, in _start_by_fork
    ret = args.func(args, dag=self.dag)
          ^^^^^^^^^^^^^^^^^^^^^^^^^^^^^
  File "/home/airflow/.local/lib/python3.12/site-packages/airflow/cli/cli_config.py", line 49, in command
    return func(*args, **kwargs)
           ^^^^^^^^^^^^^^^^^^^^^
  File "/home/airflow/.local/lib/python3.12/site-packages/airflow/utils/cli.py", line 116, in wrapper
    return f(*args, **kwargs)
           ^^^^^^^^^^^^^^^^^^
  File "/home/airflow/.local/lib/python3.12/site-packages/airflow/cli/commands/task_command.py", line 483, in task_run
    task_return_code = _run_task_by_selected_method(args, _dag, ti)
                       ^^^^^^^^^^^^^^^^^^^^^^^^^^^^^^^^^^^^^^^^^^^^
  File "/home/airflow/.local/lib/python3.12/site-packages/airflow/cli/commands/task_command.py", line 256, in _run_task_by_selected_method
    return _run_raw_task(args, ti)
           ^^^^^^^^^^^^^^^^^^^^^^^
  File "/home/airflow/.local/lib/python3.12/site-packages/airflow/cli/commands/task_command.py", line 341, in _run_raw_task
    return ti._run_raw_task(
           ^^^^^^^^^^^^^^^^^
  File "/home/airflow/.local/lib/python3.12/site-packages/airflow/utils/session.py", line 97, in wrapper
    return func(*args, session=session, **kwargs)
           ^^^^^^^^^^^^^^^^^^^^^^^^^^^^^^^^^^^^^^
  File "/home/airflow/.local/lib/python3.12/site-packages/airflow/models/taskinstance.py", line 3006, in _run_raw_task
    return _run_raw_task(
           ^^^^^^^^^^^^^^
  File "/home/airflow/.local/lib/python3.12/site-packages/airflow/models/taskinstance.py", line 274, in _run_raw_task
    TaskInstance._execute_task_with_callbacks(
  File "/home/airflow/.local/lib/python3.12/site-packages/airflow/models/taskinstance.py", line 3161, in _execute_task_with_callbacks
    result = self._execute_task(context, task_orig)
             ^^^^^^^^^^^^^^^^^^^^^^^^^^^^^^^^^^^^^^
  File "/home/airflow/.local/lib/python3.12/site-packages/airflow/models/taskinstance.py", line 3185, in _execute_task
    return _execute_task(self, context, task_orig)
           ^^^^^^^^^^^^^^^^^^^^^^^^^^^^^^^^^^^^^^^
  File "/home/airflow/.local/lib/python3.12/site-packages/airflow/models/taskinstance.py", line 768, in _execute_task
    result = _execute_callable(context=context, **execute_callable_kwargs)
             ^^^^^^^^^^^^^^^^^^^^^^^^^^^^^^^^^^^^^^^^^^^^^^^^^^^^^^^^^^^^^
  File "/home/airflow/.local/lib/python3.12/site-packages/airflow/models/taskinstance.py", line 734, in _execute_callable
    return ExecutionCallableRunner(
           ^^^^^^^^^^^^^^^^^^^^^^^^
  File "/home/airflow/.local/lib/python3.12/site-packages/airflow/utils/operator_helpers.py", line 252, in run
    return self.func(*args, **kwargs)
           ^^^^^^^^^^^^^^^^^^^^^^^^^^
  File "/home/airflow/.local/lib/python3.12/site-packages/airflow/models/baseoperator.py", line 424, in wrapper
    return func(self, *args, **kwargs)
           ^^^^^^^^^^^^^^^^^^^^^^^^^^^
  File "/home/airflow/.local/lib/python3.12/site-packages/airflow/operators/python.py", line 238, in execute
    return_value = self.execute_callable()
                   ^^^^^^^^^^^^^^^^^^^^^^^
  File "/home/airflow/.local/lib/python3.12/site-packages/airflow/operators/python.py", line 256, in execute_callable
    return runner.run(*self.op_args, **self.op_kwargs)
           ^^^^^^^^^^^^^^^^^^^^^^^^^^^^^^^^^^^^^^^^^^^
  File "/home/airflow/.local/lib/python3.12/site-packages/airflow/utils/operator_helpers.py", line 252, in run
    return self.func(*args, **kwargs)
           ^^^^^^^^^^^^^^^^^^^^^^^^^^
  File "/opt/airflow/dags/scripts/download_data.py", line 13, in download_data
    os.makedirs(data_dir, exist_ok=True)
  File "<frozen os>", line 225, in makedirs
PermissionError: [Errno 13] Permission denied: '../data'
[2025-04-01T11:32:05.560+0000] {local_task_job_runner.py:266} INFO - Task exited with return code 1
[2025-04-01T11:32:05.662+0000] {taskinstance.py:3901} INFO - 0 downstream tasks scheduled from follow-on schedule check
[2025-04-01T11:32:05.671+0000] {local_task_job_runner.py:245} INFO - ::endgroup::
