[2025-04-06T13:39:13.084+0100] {local_task_job_runner.py:123} INFO - ::group::Pre task execution logs
[2025-04-06T13:39:13.101+0100] {taskinstance.py:2614} INFO - Dependencies all met for dep_context=non-requeueable deps ti=<TaskInstance: premier_league_data_pipeline.load_data_to_postgres manual__2025-04-06T12:38:13.601216+00:00 [queued]>
[2025-04-06T13:39:13.108+0100] {taskinstance.py:2614} INFO - Dependencies all met for dep_context=requeueable deps ti=<TaskInstance: premier_league_data_pipeline.load_data_to_postgres manual__2025-04-06T12:38:13.601216+00:00 [queued]>
[2025-04-06T13:39:13.108+0100] {taskinstance.py:2867} INFO - Starting attempt 1 of 2
[2025-04-06T13:39:13.120+0100] {taskinstance.py:2890} INFO - Executing <Task(PythonOperator): load_data_to_postgres> on 2025-04-06 12:38:13.601216+00:00
[2025-04-06T13:39:13.123+0100] {standard_task_runner.py:72} INFO - Started process 17864 to run task
[2025-04-06T13:39:13.126+0100] {standard_task_runner.py:104} INFO - Running: ['airflow', 'tasks', 'run', 'premier_league_data_pipeline', 'load_data_to_postgres', 'manual__2025-04-06T12:38:13.601216+00:00', '--job-id', '9', '--raw', '--subdir', 'DAGS_FOLDER/premier_league_dag.py', '--cfg-path', '/tmp/tmpmur1sxlx']
[2025-04-06T13:39:13.126+0100] {standard_task_runner.py:105} INFO - Job 9: Subtask load_data_to_postgres
[2025-04-06T13:39:13.154+0100] {task_command.py:467} INFO - Running <TaskInstance: premier_league_data_pipeline.load_data_to_postgres manual__2025-04-06T12:38:13.601216+00:00 [running]> on host dell-Latitude-5480
[2025-04-06T13:39:13.201+0100] {taskinstance.py:3134} INFO - Exporting env vars: AIRFLOW_CTX_DAG_OWNER='Victory' AIRFLOW_CTX_DAG_ID='premier_league_data_pipeline' AIRFLOW_CTX_TASK_ID='load_data_to_postgres' AIRFLOW_CTX_EXECUTION_DATE='2025-04-06T12:38:13.601216+00:00' AIRFLOW_CTX_TRY_NUMBER='1' AIRFLOW_CTX_DAG_RUN_ID='manual__2025-04-06T12:38:13.601216+00:00'
[2025-04-06T13:39:13.202+0100] {logging_mixin.py:190} INFO - Task instance is in running state
[2025-04-06T13:39:13.202+0100] {logging_mixin.py:190} INFO -  Previous state of the Task instance: queued
[2025-04-06T13:39:13.202+0100] {logging_mixin.py:190} INFO - Current task name:load_data_to_postgres state:running start_date:2025-04-06 12:39:13.102083+00:00
[2025-04-06T13:39:13.202+0100] {logging_mixin.py:190} INFO - Dag name:premier_league_data_pipeline and current dag run status:running
[2025-04-06T13:39:13.202+0100] {taskinstance.py:732} INFO - ::endgroup::
[2025-04-06T13:39:13.209+0100] {taskinstance.py:3313} ERROR - Task failed with exception
Traceback (most recent call last):
  File "/home/Data_Professional/PycharmProjects/DE_Zoomcamp_Capstone_Project/.venv/lib/python3.10/site-packages/sqlalchemy/engine/base.py", line 3371, in _wrap_pool_connect
    return fn()
  File "/home/Data_Professional/PycharmProjects/DE_Zoomcamp_Capstone_Project/.venv/lib/python3.10/site-packages/sqlalchemy/pool/base.py", line 327, in connect
    return _ConnectionFairy._checkout(self)
  File "/home/Data_Professional/PycharmProjects/DE_Zoomcamp_Capstone_Project/.venv/lib/python3.10/site-packages/sqlalchemy/pool/base.py", line 894, in _checkout
    fairy = _ConnectionRecord.checkout(pool)
  File "/home/Data_Professional/PycharmProjects/DE_Zoomcamp_Capstone_Project/.venv/lib/python3.10/site-packages/sqlalchemy/pool/base.py", line 493, in checkout
    rec = pool._do_get()
  File "/home/Data_Professional/PycharmProjects/DE_Zoomcamp_Capstone_Project/.venv/lib/python3.10/site-packages/sqlalchemy/pool/impl.py", line 145, in _do_get
    with util.safe_reraise():
  File "/home/Data_Professional/PycharmProjects/DE_Zoomcamp_Capstone_Project/.venv/lib/python3.10/site-packages/sqlalchemy/util/langhelpers.py", line 70, in __exit__
    compat.raise_(
  File "/home/Data_Professional/PycharmProjects/DE_Zoomcamp_Capstone_Project/.venv/lib/python3.10/site-packages/sqlalchemy/util/compat.py", line 211, in raise_
    raise exception
  File "/home/Data_Professional/PycharmProjects/DE_Zoomcamp_Capstone_Project/.venv/lib/python3.10/site-packages/sqlalchemy/pool/impl.py", line 143, in _do_get
    return self._create_connection()
  File "/home/Data_Professional/PycharmProjects/DE_Zoomcamp_Capstone_Project/.venv/lib/python3.10/site-packages/sqlalchemy/pool/base.py", line 273, in _create_connection
    return _ConnectionRecord(self)
  File "/home/Data_Professional/PycharmProjects/DE_Zoomcamp_Capstone_Project/.venv/lib/python3.10/site-packages/sqlalchemy/pool/base.py", line 388, in __init__
    self.__connect()
  File "/home/Data_Professional/PycharmProjects/DE_Zoomcamp_Capstone_Project/.venv/lib/python3.10/site-packages/sqlalchemy/pool/base.py", line 690, in __connect
    with util.safe_reraise():
  File "/home/Data_Professional/PycharmProjects/DE_Zoomcamp_Capstone_Project/.venv/lib/python3.10/site-packages/sqlalchemy/util/langhelpers.py", line 70, in __exit__
    compat.raise_(
  File "/home/Data_Professional/PycharmProjects/DE_Zoomcamp_Capstone_Project/.venv/lib/python3.10/site-packages/sqlalchemy/util/compat.py", line 211, in raise_
    raise exception
  File "/home/Data_Professional/PycharmProjects/DE_Zoomcamp_Capstone_Project/.venv/lib/python3.10/site-packages/sqlalchemy/pool/base.py", line 686, in __connect
    self.dbapi_connection = connection = pool._invoke_creator(self)
  File "/home/Data_Professional/PycharmProjects/DE_Zoomcamp_Capstone_Project/.venv/lib/python3.10/site-packages/sqlalchemy/engine/create.py", line 574, in connect
    return dialect.connect(*cargs, **cparams)
  File "/home/Data_Professional/PycharmProjects/DE_Zoomcamp_Capstone_Project/.venv/lib/python3.10/site-packages/sqlalchemy/engine/default.py", line 598, in connect
    return self.dbapi.connect(*cargs, **cparams)
  File "/home/Data_Professional/PycharmProjects/DE_Zoomcamp_Capstone_Project/.venv/lib/python3.10/site-packages/psycopg2/__init__.py", line 122, in connect
    conn = _connect(dsn, connection_factory=connection_factory, **kwasync)
psycopg2.OperationalError: connection to server at "127.0.0.1", port 5433 failed: Connection refused
	Is the server running on that host and accepting TCP/IP connections?


The above exception was the direct cause of the following exception:

Traceback (most recent call last):
  File "/home/Data_Professional/PycharmProjects/DE_Zoomcamp_Capstone_Project/.venv/lib/python3.10/site-packages/airflow/models/taskinstance.py", line 768, in _execute_task
    result = _execute_callable(context=context, **execute_callable_kwargs)
  File "/home/Data_Professional/PycharmProjects/DE_Zoomcamp_Capstone_Project/.venv/lib/python3.10/site-packages/airflow/models/taskinstance.py", line 734, in _execute_callable
    return ExecutionCallableRunner(
  File "/home/Data_Professional/PycharmProjects/DE_Zoomcamp_Capstone_Project/.venv/lib/python3.10/site-packages/airflow/utils/operator_helpers.py", line 252, in run
    return self.func(*args, **kwargs)
  File "/home/Data_Professional/PycharmProjects/DE_Zoomcamp_Capstone_Project/.venv/lib/python3.10/site-packages/airflow/models/baseoperator.py", line 424, in wrapper
    return func(self, *args, **kwargs)
  File "/home/Data_Professional/PycharmProjects/DE_Zoomcamp_Capstone_Project/.venv/lib/python3.10/site-packages/airflow/operators/python.py", line 238, in execute
    return_value = self.execute_callable()
  File "/home/Data_Professional/PycharmProjects/DE_Zoomcamp_Capstone_Project/.venv/lib/python3.10/site-packages/airflow/operators/python.py", line 256, in execute_callable
    return runner.run(*self.op_args, **self.op_kwargs)
  File "/home/Data_Professional/PycharmProjects/DE_Zoomcamp_Capstone_Project/.venv/lib/python3.10/site-packages/airflow/utils/operator_helpers.py", line 252, in run
    return self.func(*args, **kwargs)
  File "/home/Data_Professional/PycharmProjects/DE_Zoomcamp_Capstone_Project/airflow/dags/scripts/ingestion_to_postgres.py", line 36, in load_data_to_postgres
    with engine.connect() as conn:
  File "/home/Data_Professional/PycharmProjects/DE_Zoomcamp_Capstone_Project/.venv/lib/python3.10/site-packages/sqlalchemy/engine/base.py", line 3325, in connect
    return self._connection_cls(self, close_with_result=close_with_result)
  File "/home/Data_Professional/PycharmProjects/DE_Zoomcamp_Capstone_Project/.venv/lib/python3.10/site-packages/sqlalchemy/engine/base.py", line 96, in __init__
    else engine.raw_connection()
  File "/home/Data_Professional/PycharmProjects/DE_Zoomcamp_Capstone_Project/.venv/lib/python3.10/site-packages/sqlalchemy/engine/base.py", line 3404, in raw_connection
    return self._wrap_pool_connect(self.pool.connect, _connection)
  File "/home/Data_Professional/PycharmProjects/DE_Zoomcamp_Capstone_Project/.venv/lib/python3.10/site-packages/sqlalchemy/engine/base.py", line 3374, in _wrap_pool_connect
    Connection._handle_dbapi_exception_noconnection(
  File "/home/Data_Professional/PycharmProjects/DE_Zoomcamp_Capstone_Project/.venv/lib/python3.10/site-packages/sqlalchemy/engine/base.py", line 2208, in _handle_dbapi_exception_noconnection
    util.raise_(
  File "/home/Data_Professional/PycharmProjects/DE_Zoomcamp_Capstone_Project/.venv/lib/python3.10/site-packages/sqlalchemy/util/compat.py", line 211, in raise_
    raise exception
  File "/home/Data_Professional/PycharmProjects/DE_Zoomcamp_Capstone_Project/.venv/lib/python3.10/site-packages/sqlalchemy/engine/base.py", line 3371, in _wrap_pool_connect
    return fn()
  File "/home/Data_Professional/PycharmProjects/DE_Zoomcamp_Capstone_Project/.venv/lib/python3.10/site-packages/sqlalchemy/pool/base.py", line 327, in connect
    return _ConnectionFairy._checkout(self)
  File "/home/Data_Professional/PycharmProjects/DE_Zoomcamp_Capstone_Project/.venv/lib/python3.10/site-packages/sqlalchemy/pool/base.py", line 894, in _checkout
    fairy = _ConnectionRecord.checkout(pool)
  File "/home/Data_Professional/PycharmProjects/DE_Zoomcamp_Capstone_Project/.venv/lib/python3.10/site-packages/sqlalchemy/pool/base.py", line 493, in checkout
    rec = pool._do_get()
  File "/home/Data_Professional/PycharmProjects/DE_Zoomcamp_Capstone_Project/.venv/lib/python3.10/site-packages/sqlalchemy/pool/impl.py", line 145, in _do_get
    with util.safe_reraise():
  File "/home/Data_Professional/PycharmProjects/DE_Zoomcamp_Capstone_Project/.venv/lib/python3.10/site-packages/sqlalchemy/util/langhelpers.py", line 70, in __exit__
    compat.raise_(
  File "/home/Data_Professional/PycharmProjects/DE_Zoomcamp_Capstone_Project/.venv/lib/python3.10/site-packages/sqlalchemy/util/compat.py", line 211, in raise_
    raise exception
  File "/home/Data_Professional/PycharmProjects/DE_Zoomcamp_Capstone_Project/.venv/lib/python3.10/site-packages/sqlalchemy/pool/impl.py", line 143, in _do_get
    return self._create_connection()
  File "/home/Data_Professional/PycharmProjects/DE_Zoomcamp_Capstone_Project/.venv/lib/python3.10/site-packages/sqlalchemy/pool/base.py", line 273, in _create_connection
    return _ConnectionRecord(self)
  File "/home/Data_Professional/PycharmProjects/DE_Zoomcamp_Capstone_Project/.venv/lib/python3.10/site-packages/sqlalchemy/pool/base.py", line 388, in __init__
    self.__connect()
  File "/home/Data_Professional/PycharmProjects/DE_Zoomcamp_Capstone_Project/.venv/lib/python3.10/site-packages/sqlalchemy/pool/base.py", line 690, in __connect
    with util.safe_reraise():
  File "/home/Data_Professional/PycharmProjects/DE_Zoomcamp_Capstone_Project/.venv/lib/python3.10/site-packages/sqlalchemy/util/langhelpers.py", line 70, in __exit__
    compat.raise_(
  File "/home/Data_Professional/PycharmProjects/DE_Zoomcamp_Capstone_Project/.venv/lib/python3.10/site-packages/sqlalchemy/util/compat.py", line 211, in raise_
    raise exception
  File "/home/Data_Professional/PycharmProjects/DE_Zoomcamp_Capstone_Project/.venv/lib/python3.10/site-packages/sqlalchemy/pool/base.py", line 686, in __connect
    self.dbapi_connection = connection = pool._invoke_creator(self)
  File "/home/Data_Professional/PycharmProjects/DE_Zoomcamp_Capstone_Project/.venv/lib/python3.10/site-packages/sqlalchemy/engine/create.py", line 574, in connect
    return dialect.connect(*cargs, **cparams)
  File "/home/Data_Professional/PycharmProjects/DE_Zoomcamp_Capstone_Project/.venv/lib/python3.10/site-packages/sqlalchemy/engine/default.py", line 598, in connect
    return self.dbapi.connect(*cargs, **cparams)
  File "/home/Data_Professional/PycharmProjects/DE_Zoomcamp_Capstone_Project/.venv/lib/python3.10/site-packages/psycopg2/__init__.py", line 122, in connect
    conn = _connect(dsn, connection_factory=connection_factory, **kwasync)
sqlalchemy.exc.OperationalError: (psycopg2.OperationalError) connection to server at "127.0.0.1", port 5433 failed: Connection refused
	Is the server running on that host and accepting TCP/IP connections?

(Background on this error at: https://sqlalche.me/e/14/e3q8)
[2025-04-06T13:39:13.221+0100] {logging_mixin.py:190} INFO - Task instance in failure state
[2025-04-06T13:39:13.221+0100] {logging_mixin.py:190} INFO - Task start:2025-04-06 12:39:13.102083+00:00 end:2025-04-06 12:39:13.221093+00:00 duration:0.11901
[2025-04-06T13:39:13.221+0100] {logging_mixin.py:190} INFO - Task:<Task(PythonOperator): load_data_to_postgres> dag:<DAG: premier_league_data_pipeline> dagrun:<DagRun premier_league_data_pipeline @ 2025-04-06 12:38:13.601216+00:00: manual__2025-04-06T12:38:13.601216+00:00, state:running, queued_at: 2025-04-06 12:38:13.618397+00:00. externally triggered: True>
[2025-04-06T13:39:13.222+0100] {logging_mixin.py:190} INFO - Failure caused by (psycopg2.OperationalError) connection to server at "127.0.0.1", port 5433 failed: Connection refused
	Is the server running on that host and accepting TCP/IP connections?

(Background on this error at: https://sqlalche.me/e/14/e3q8)
[2025-04-06T13:39:13.222+0100] {taskinstance.py:1226} INFO - Marking task as UP_FOR_RETRY. dag_id=premier_league_data_pipeline, task_id=load_data_to_postgres, run_id=manual__2025-04-06T12:38:13.601216+00:00, execution_date=20250406T123813, start_date=20250406T123913, end_date=20250406T123913
[2025-04-06T13:39:13.328+0100] {taskinstance.py:341} INFO - ::group::Post task execution logs
[2025-04-06T13:39:13.328+0100] {standard_task_runner.py:124} ERROR - Failed to execute job 9 for task load_data_to_postgres ((psycopg2.OperationalError) connection to server at "127.0.0.1", port 5433 failed: Connection refused
	Is the server running on that host and accepting TCP/IP connections?

(Background on this error at: https://sqlalche.me/e/14/e3q8); 17864)
Traceback (most recent call last):
  File "/home/Data_Professional/PycharmProjects/DE_Zoomcamp_Capstone_Project/.venv/lib/python3.10/site-packages/sqlalchemy/engine/base.py", line 3371, in _wrap_pool_connect
    return fn()
  File "/home/Data_Professional/PycharmProjects/DE_Zoomcamp_Capstone_Project/.venv/lib/python3.10/site-packages/sqlalchemy/pool/base.py", line 327, in connect
    return _ConnectionFairy._checkout(self)
  File "/home/Data_Professional/PycharmProjects/DE_Zoomcamp_Capstone_Project/.venv/lib/python3.10/site-packages/sqlalchemy/pool/base.py", line 894, in _checkout
    fairy = _ConnectionRecord.checkout(pool)
  File "/home/Data_Professional/PycharmProjects/DE_Zoomcamp_Capstone_Project/.venv/lib/python3.10/site-packages/sqlalchemy/pool/base.py", line 493, in checkout
    rec = pool._do_get()
  File "/home/Data_Professional/PycharmProjects/DE_Zoomcamp_Capstone_Project/.venv/lib/python3.10/site-packages/sqlalchemy/pool/impl.py", line 145, in _do_get
    with util.safe_reraise():
  File "/home/Data_Professional/PycharmProjects/DE_Zoomcamp_Capstone_Project/.venv/lib/python3.10/site-packages/sqlalchemy/util/langhelpers.py", line 70, in __exit__
    compat.raise_(
  File "/home/Data_Professional/PycharmProjects/DE_Zoomcamp_Capstone_Project/.venv/lib/python3.10/site-packages/sqlalchemy/util/compat.py", line 211, in raise_
    raise exception
  File "/home/Data_Professional/PycharmProjects/DE_Zoomcamp_Capstone_Project/.venv/lib/python3.10/site-packages/sqlalchemy/pool/impl.py", line 143, in _do_get
    return self._create_connection()
  File "/home/Data_Professional/PycharmProjects/DE_Zoomcamp_Capstone_Project/.venv/lib/python3.10/site-packages/sqlalchemy/pool/base.py", line 273, in _create_connection
    return _ConnectionRecord(self)
  File "/home/Data_Professional/PycharmProjects/DE_Zoomcamp_Capstone_Project/.venv/lib/python3.10/site-packages/sqlalchemy/pool/base.py", line 388, in __init__
    self.__connect()
  File "/home/Data_Professional/PycharmProjects/DE_Zoomcamp_Capstone_Project/.venv/lib/python3.10/site-packages/sqlalchemy/pool/base.py", line 690, in __connect
    with util.safe_reraise():
  File "/home/Data_Professional/PycharmProjects/DE_Zoomcamp_Capstone_Project/.venv/lib/python3.10/site-packages/sqlalchemy/util/langhelpers.py", line 70, in __exit__
    compat.raise_(
  File "/home/Data_Professional/PycharmProjects/DE_Zoomcamp_Capstone_Project/.venv/lib/python3.10/site-packages/sqlalchemy/util/compat.py", line 211, in raise_
    raise exception
  File "/home/Data_Professional/PycharmProjects/DE_Zoomcamp_Capstone_Project/.venv/lib/python3.10/site-packages/sqlalchemy/pool/base.py", line 686, in __connect
    self.dbapi_connection = connection = pool._invoke_creator(self)
  File "/home/Data_Professional/PycharmProjects/DE_Zoomcamp_Capstone_Project/.venv/lib/python3.10/site-packages/sqlalchemy/engine/create.py", line 574, in connect
    return dialect.connect(*cargs, **cparams)
  File "/home/Data_Professional/PycharmProjects/DE_Zoomcamp_Capstone_Project/.venv/lib/python3.10/site-packages/sqlalchemy/engine/default.py", line 598, in connect
    return self.dbapi.connect(*cargs, **cparams)
  File "/home/Data_Professional/PycharmProjects/DE_Zoomcamp_Capstone_Project/.venv/lib/python3.10/site-packages/psycopg2/__init__.py", line 122, in connect
    conn = _connect(dsn, connection_factory=connection_factory, **kwasync)
psycopg2.OperationalError: connection to server at "127.0.0.1", port 5433 failed: Connection refused
	Is the server running on that host and accepting TCP/IP connections?


The above exception was the direct cause of the following exception:

Traceback (most recent call last):
  File "/home/Data_Professional/PycharmProjects/DE_Zoomcamp_Capstone_Project/.venv/lib/python3.10/site-packages/airflow/task/task_runner/standard_task_runner.py", line 117, in _start_by_fork
    ret = args.func(args, dag=self.dag)
  File "/home/Data_Professional/PycharmProjects/DE_Zoomcamp_Capstone_Project/.venv/lib/python3.10/site-packages/airflow/cli/cli_config.py", line 49, in command
    return func(*args, **kwargs)
  File "/home/Data_Professional/PycharmProjects/DE_Zoomcamp_Capstone_Project/.venv/lib/python3.10/site-packages/airflow/utils/cli.py", line 116, in wrapper
    return f(*args, **kwargs)
  File "/home/Data_Professional/PycharmProjects/DE_Zoomcamp_Capstone_Project/.venv/lib/python3.10/site-packages/airflow/cli/commands/task_command.py", line 483, in task_run
    task_return_code = _run_task_by_selected_method(args, _dag, ti)
  File "/home/Data_Professional/PycharmProjects/DE_Zoomcamp_Capstone_Project/.venv/lib/python3.10/site-packages/airflow/cli/commands/task_command.py", line 256, in _run_task_by_selected_method
    return _run_raw_task(args, ti)
  File "/home/Data_Professional/PycharmProjects/DE_Zoomcamp_Capstone_Project/.venv/lib/python3.10/site-packages/airflow/cli/commands/task_command.py", line 341, in _run_raw_task
    return ti._run_raw_task(
  File "/home/Data_Professional/PycharmProjects/DE_Zoomcamp_Capstone_Project/.venv/lib/python3.10/site-packages/airflow/utils/session.py", line 97, in wrapper
    return func(*args, session=session, **kwargs)
  File "/home/Data_Professional/PycharmProjects/DE_Zoomcamp_Capstone_Project/.venv/lib/python3.10/site-packages/airflow/models/taskinstance.py", line 3006, in _run_raw_task
    return _run_raw_task(
  File "/home/Data_Professional/PycharmProjects/DE_Zoomcamp_Capstone_Project/.venv/lib/python3.10/site-packages/airflow/models/taskinstance.py", line 274, in _run_raw_task
    TaskInstance._execute_task_with_callbacks(
  File "/home/Data_Professional/PycharmProjects/DE_Zoomcamp_Capstone_Project/.venv/lib/python3.10/site-packages/airflow/models/taskinstance.py", line 3161, in _execute_task_with_callbacks
    result = self._execute_task(context, task_orig)
  File "/home/Data_Professional/PycharmProjects/DE_Zoomcamp_Capstone_Project/.venv/lib/python3.10/site-packages/airflow/models/taskinstance.py", line 3185, in _execute_task
    return _execute_task(self, context, task_orig)
  File "/home/Data_Professional/PycharmProjects/DE_Zoomcamp_Capstone_Project/.venv/lib/python3.10/site-packages/airflow/models/taskinstance.py", line 768, in _execute_task
    result = _execute_callable(context=context, **execute_callable_kwargs)
  File "/home/Data_Professional/PycharmProjects/DE_Zoomcamp_Capstone_Project/.venv/lib/python3.10/site-packages/airflow/models/taskinstance.py", line 734, in _execute_callable
    return ExecutionCallableRunner(
  File "/home/Data_Professional/PycharmProjects/DE_Zoomcamp_Capstone_Project/.venv/lib/python3.10/site-packages/airflow/utils/operator_helpers.py", line 252, in run
    return self.func(*args, **kwargs)
  File "/home/Data_Professional/PycharmProjects/DE_Zoomcamp_Capstone_Project/.venv/lib/python3.10/site-packages/airflow/models/baseoperator.py", line 424, in wrapper
    return func(self, *args, **kwargs)
  File "/home/Data_Professional/PycharmProjects/DE_Zoomcamp_Capstone_Project/.venv/lib/python3.10/site-packages/airflow/operators/python.py", line 238, in execute
    return_value = self.execute_callable()
  File "/home/Data_Professional/PycharmProjects/DE_Zoomcamp_Capstone_Project/.venv/lib/python3.10/site-packages/airflow/operators/python.py", line 256, in execute_callable
    return runner.run(*self.op_args, **self.op_kwargs)
  File "/home/Data_Professional/PycharmProjects/DE_Zoomcamp_Capstone_Project/.venv/lib/python3.10/site-packages/airflow/utils/operator_helpers.py", line 252, in run
    return self.func(*args, **kwargs)
  File "/home/Data_Professional/PycharmProjects/DE_Zoomcamp_Capstone_Project/airflow/dags/scripts/ingestion_to_postgres.py", line 36, in load_data_to_postgres
    with engine.connect() as conn:
  File "/home/Data_Professional/PycharmProjects/DE_Zoomcamp_Capstone_Project/.venv/lib/python3.10/site-packages/sqlalchemy/engine/base.py", line 3325, in connect
    return self._connection_cls(self, close_with_result=close_with_result)
  File "/home/Data_Professional/PycharmProjects/DE_Zoomcamp_Capstone_Project/.venv/lib/python3.10/site-packages/sqlalchemy/engine/base.py", line 96, in __init__
    else engine.raw_connection()
  File "/home/Data_Professional/PycharmProjects/DE_Zoomcamp_Capstone_Project/.venv/lib/python3.10/site-packages/sqlalchemy/engine/base.py", line 3404, in raw_connection
    return self._wrap_pool_connect(self.pool.connect, _connection)
  File "/home/Data_Professional/PycharmProjects/DE_Zoomcamp_Capstone_Project/.venv/lib/python3.10/site-packages/sqlalchemy/engine/base.py", line 3374, in _wrap_pool_connect
    Connection._handle_dbapi_exception_noconnection(
  File "/home/Data_Professional/PycharmProjects/DE_Zoomcamp_Capstone_Project/.venv/lib/python3.10/site-packages/sqlalchemy/engine/base.py", line 2208, in _handle_dbapi_exception_noconnection
    util.raise_(
  File "/home/Data_Professional/PycharmProjects/DE_Zoomcamp_Capstone_Project/.venv/lib/python3.10/site-packages/sqlalchemy/util/compat.py", line 211, in raise_
    raise exception
  File "/home/Data_Professional/PycharmProjects/DE_Zoomcamp_Capstone_Project/.venv/lib/python3.10/site-packages/sqlalchemy/engine/base.py", line 3371, in _wrap_pool_connect
    return fn()
  File "/home/Data_Professional/PycharmProjects/DE_Zoomcamp_Capstone_Project/.venv/lib/python3.10/site-packages/sqlalchemy/pool/base.py", line 327, in connect
    return _ConnectionFairy._checkout(self)
  File "/home/Data_Professional/PycharmProjects/DE_Zoomcamp_Capstone_Project/.venv/lib/python3.10/site-packages/sqlalchemy/pool/base.py", line 894, in _checkout
    fairy = _ConnectionRecord.checkout(pool)
  File "/home/Data_Professional/PycharmProjects/DE_Zoomcamp_Capstone_Project/.venv/lib/python3.10/site-packages/sqlalchemy/pool/base.py", line 493, in checkout
    rec = pool._do_get()
  File "/home/Data_Professional/PycharmProjects/DE_Zoomcamp_Capstone_Project/.venv/lib/python3.10/site-packages/sqlalchemy/pool/impl.py", line 145, in _do_get
    with util.safe_reraise():
  File "/home/Data_Professional/PycharmProjects/DE_Zoomcamp_Capstone_Project/.venv/lib/python3.10/site-packages/sqlalchemy/util/langhelpers.py", line 70, in __exit__
    compat.raise_(
  File "/home/Data_Professional/PycharmProjects/DE_Zoomcamp_Capstone_Project/.venv/lib/python3.10/site-packages/sqlalchemy/util/compat.py", line 211, in raise_
    raise exception
  File "/home/Data_Professional/PycharmProjects/DE_Zoomcamp_Capstone_Project/.venv/lib/python3.10/site-packages/sqlalchemy/pool/impl.py", line 143, in _do_get
    return self._create_connection()
  File "/home/Data_Professional/PycharmProjects/DE_Zoomcamp_Capstone_Project/.venv/lib/python3.10/site-packages/sqlalchemy/pool/base.py", line 273, in _create_connection
    return _ConnectionRecord(self)
  File "/home/Data_Professional/PycharmProjects/DE_Zoomcamp_Capstone_Project/.venv/lib/python3.10/site-packages/sqlalchemy/pool/base.py", line 388, in __init__
    self.__connect()
  File "/home/Data_Professional/PycharmProjects/DE_Zoomcamp_Capstone_Project/.venv/lib/python3.10/site-packages/sqlalchemy/pool/base.py", line 690, in __connect
    with util.safe_reraise():
  File "/home/Data_Professional/PycharmProjects/DE_Zoomcamp_Capstone_Project/.venv/lib/python3.10/site-packages/sqlalchemy/util/langhelpers.py", line 70, in __exit__
    compat.raise_(
  File "/home/Data_Professional/PycharmProjects/DE_Zoomcamp_Capstone_Project/.venv/lib/python3.10/site-packages/sqlalchemy/util/compat.py", line 211, in raise_
    raise exception
  File "/home/Data_Professional/PycharmProjects/DE_Zoomcamp_Capstone_Project/.venv/lib/python3.10/site-packages/sqlalchemy/pool/base.py", line 686, in __connect
    self.dbapi_connection = connection = pool._invoke_creator(self)
  File "/home/Data_Professional/PycharmProjects/DE_Zoomcamp_Capstone_Project/.venv/lib/python3.10/site-packages/sqlalchemy/engine/create.py", line 574, in connect
    return dialect.connect(*cargs, **cparams)
  File "/home/Data_Professional/PycharmProjects/DE_Zoomcamp_Capstone_Project/.venv/lib/python3.10/site-packages/sqlalchemy/engine/default.py", line 598, in connect
    return self.dbapi.connect(*cargs, **cparams)
  File "/home/Data_Professional/PycharmProjects/DE_Zoomcamp_Capstone_Project/.venv/lib/python3.10/site-packages/psycopg2/__init__.py", line 122, in connect
    conn = _connect(dsn, connection_factory=connection_factory, **kwasync)
sqlalchemy.exc.OperationalError: (psycopg2.OperationalError) connection to server at "127.0.0.1", port 5433 failed: Connection refused
	Is the server running on that host and accepting TCP/IP connections?

(Background on this error at: https://sqlalche.me/e/14/e3q8)
[2025-04-06T13:39:13.338+0100] {local_task_job_runner.py:266} INFO - Task exited with return code 1
[2025-04-06T13:39:13.354+0100] {taskinstance.py:3901} INFO - 0 downstream tasks scheduled from follow-on schedule check
[2025-04-06T13:39:13.354+0100] {local_task_job_runner.py:245} INFO - ::endgroup::
