[2025-04-06T13:12:22.036+0100] {processor.py:186} INFO - Started process (PID=12466) to work on /home/Data_Professional/PycharmProjects/DE_Zoomcamp_Capstone_Project/.venv/lib/python3.10/site-packages/airflow/example_dags/example_local_kubernetes_executor.py
[2025-04-06T13:12:22.037+0100] {processor.py:914} INFO - Processing file /home/Data_Professional/PycharmProjects/DE_Zoomcamp_Capstone_Project/.venv/lib/python3.10/site-packages/airflow/example_dags/example_local_kubernetes_executor.py for tasks to queue
[2025-04-06T13:12:22.039+0100] {logging_mixin.py:190} INFO - [2025-04-06T13:12:22.039+0100] {dagbag.py:588} INFO - Filling up the DagBag from /home/Data_Professional/PycharmProjects/DE_Zoomcamp_Capstone_Project/.venv/lib/python3.10/site-packages/airflow/example_dags/example_local_kubernetes_executor.py
[2025-04-06T13:12:22.043+0100] {logging_mixin.py:190} INFO - [2025-04-06T13:12:22.042+0100] {example_local_kubernetes_executor.py:40} WARNING - Could not import DAGs in example_local_kubernetes_executor.py
Traceback (most recent call last):
  File "/home/Data_Professional/PycharmProjects/DE_Zoomcamp_Capstone_Project/.venv/lib/python3.10/site-packages/airflow/example_dags/example_local_kubernetes_executor.py", line 38, in <module>
    from kubernetes.client import models as k8s
ModuleNotFoundError: No module named 'kubernetes'
[2025-04-06T13:12:22.043+0100] {logging_mixin.py:190} INFO - [2025-04-06T13:12:22.043+0100] {example_local_kubernetes_executor.py:41} WARNING - Install Kubernetes dependencies with: pip install apache-airflow[cncf.kubernetes]
[2025-04-06T13:12:22.044+0100] {processor.py:927} WARNING - No viable dags retrieved from /home/Data_Professional/PycharmProjects/DE_Zoomcamp_Capstone_Project/.venv/lib/python3.10/site-packages/airflow/example_dags/example_local_kubernetes_executor.py
[2025-04-06T13:12:22.053+0100] {processor.py:208} INFO - Processing /home/Data_Professional/PycharmProjects/DE_Zoomcamp_Capstone_Project/.venv/lib/python3.10/site-packages/airflow/example_dags/example_local_kubernetes_executor.py took 0.024 seconds
