[2025-04-01T10:44:35.548+0000] {local_task_job_runner.py:123} INFO - ::group::Pre task execution logs
[2025-04-01T10:44:35.657+0000] {taskinstance.py:2614} INFO - Dependencies all met for dep_context=non-requeueable deps ti=<TaskInstance: premier_league_ingestion.download_data_2019_20 scheduled__2025-03-23T00:00:00+00:00 [queued]>
[2025-04-01T10:44:35.770+0000] {taskinstance.py:2614} INFO - Dependencies all met for dep_context=requeueable deps ti=<TaskInstance: premier_league_ingestion.download_data_2019_20 scheduled__2025-03-23T00:00:00+00:00 [queued]>
[2025-04-01T10:44:35.776+0000] {taskinstance.py:2867} INFO - Starting attempt 2 of 2
[2025-04-01T10:44:36.004+0000] {taskinstance.py:2890} INFO - Executing <Task(PythonOperator): download_data_2019_20> on 2025-03-23 00:00:00+00:00
[2025-04-01T10:44:36.037+0000] {warnings.py:112} WARNING - /home/***/.local/lib/python3.12/site-packages/***/task/task_runner/standard_task_runner.py:70: DeprecationWarning: This process (pid=247) is multi-threaded, use of fork() may lead to deadlocks in the child.
  pid = os.fork()

[2025-04-01T10:44:36.051+0000] {standard_task_runner.py:72} INFO - Started process 255 to run task
[2025-04-01T10:44:36.048+0000] {standard_task_runner.py:104} INFO - Running: ['***', 'tasks', 'run', 'premier_league_ingestion', 'download_data_2019_20', 'scheduled__2025-03-23T00:00:00+00:00', '--job-id', '10', '--raw', '--subdir', 'DAGS_FOLDER/premier_league_dag.py', '--cfg-path', '/tmp/tmpo840ffaw']
[2025-04-01T10:44:36.082+0000] {standard_task_runner.py:105} INFO - Job 10: Subtask download_data_2019_20
[2025-04-01T10:44:36.303+0000] {task_command.py:467} INFO - Running <TaskInstance: premier_league_ingestion.download_data_2019_20 scheduled__2025-03-23T00:00:00+00:00 [running]> on host 6cd6fb1a2334
[2025-04-01T10:44:36.907+0000] {taskinstance.py:3134} INFO - Exporting env vars: AIRFLOW_CTX_DAG_OWNER='***' AIRFLOW_CTX_DAG_ID='premier_league_ingestion' AIRFLOW_CTX_TASK_ID='download_data_2019_20' AIRFLOW_CTX_EXECUTION_DATE='2025-03-23T00:00:00+00:00' AIRFLOW_CTX_TRY_NUMBER='2' AIRFLOW_CTX_DAG_RUN_ID='scheduled__2025-03-23T00:00:00+00:00'
[2025-04-01T10:44:36.926+0000] {taskinstance.py:732} INFO - ::endgroup::
[2025-04-01T10:44:36.975+0000] {taskinstance.py:3313} ERROR - Task failed with exception
Traceback (most recent call last):
  File "/home/airflow/.local/lib/python3.12/site-packages/airflow/models/taskinstance.py", line 768, in _execute_task
    result = _execute_callable(context=context, **execute_callable_kwargs)
             ^^^^^^^^^^^^^^^^^^^^^^^^^^^^^^^^^^^^^^^^^^^^^^^^^^^^^^^^^^^^^
  File "/home/airflow/.local/lib/python3.12/site-packages/airflow/models/taskinstance.py", line 734, in _execute_callable
    return ExecutionCallableRunner(
           ^^^^^^^^^^^^^^^^^^^^^^^^
  File "/home/airflow/.local/lib/python3.12/site-packages/airflow/utils/operator_helpers.py", line 252, in run
    return self.func(*args, **kwargs)
           ^^^^^^^^^^^^^^^^^^^^^^^^^^
  File "/home/airflow/.local/lib/python3.12/site-packages/airflow/models/baseoperator.py", line 424, in wrapper
    return func(self, *args, **kwargs)
           ^^^^^^^^^^^^^^^^^^^^^^^^^^^
  File "/home/airflow/.local/lib/python3.12/site-packages/airflow/operators/python.py", line 238, in execute
    return_value = self.execute_callable()
                   ^^^^^^^^^^^^^^^^^^^^^^^
  File "/home/airflow/.local/lib/python3.12/site-packages/airflow/operators/python.py", line 256, in execute_callable
    return runner.run(*self.op_args, **self.op_kwargs)
           ^^^^^^^^^^^^^^^^^^^^^^^^^^^^^^^^^^^^^^^^^^^
  File "/home/airflow/.local/lib/python3.12/site-packages/airflow/utils/operator_helpers.py", line 252, in run
    return self.func(*args, **kwargs)
           ^^^^^^^^^^^^^^^^^^^^^^^^^^
  File "/opt/airflow/dags/scripts/download_data.py", line 11, in download_data
    os.makedirs(data_dir, exist_ok=True)
  File "<frozen os>", line 225, in makedirs
PermissionError: [Errno 13] Permission denied: '../Data'
[2025-04-01T10:44:37.025+0000] {taskinstance.py:1226} INFO - Marking task as FAILED. dag_id=premier_league_ingestion, task_id=download_data_2019_20, run_id=scheduled__2025-03-23T00:00:00+00:00, execution_date=20250323T000000, start_date=20250401T104435, end_date=20250401T104437
[2025-04-01T10:44:37.247+0000] {taskinstance.py:341} INFO - ::group::Post task execution logs
[2025-04-01T10:44:37.257+0000] {standard_task_runner.py:124} ERROR - Failed to execute job 10 for task download_data_2019_20 ([Errno 13] Permission denied: '../Data'; 255)
Traceback (most recent call last):
  File "/home/airflow/.local/lib/python3.12/site-packages/airflow/task/task_runner/standard_task_runner.py", line 117, in _start_by_fork
    ret = args.func(args, dag=self.dag)
          ^^^^^^^^^^^^^^^^^^^^^^^^^^^^^
  File "/home/airflow/.local/lib/python3.12/site-packages/airflow/cli/cli_config.py", line 49, in command
    return func(*args, **kwargs)
           ^^^^^^^^^^^^^^^^^^^^^
  File "/home/airflow/.local/lib/python3.12/site-packages/airflow/utils/cli.py", line 116, in wrapper
    return f(*args, **kwargs)
           ^^^^^^^^^^^^^^^^^^
  File "/home/airflow/.local/lib/python3.12/site-packages/airflow/cli/commands/task_command.py", line 483, in task_run
    task_return_code = _run_task_by_selected_method(args, _dag, ti)
                       ^^^^^^^^^^^^^^^^^^^^^^^^^^^^^^^^^^^^^^^^^^^^
  File "/home/airflow/.local/lib/python3.12/site-packages/airflow/cli/commands/task_command.py", line 256, in _run_task_by_selected_method
    return _run_raw_task(args, ti)
           ^^^^^^^^^^^^^^^^^^^^^^^
  File "/home/airflow/.local/lib/python3.12/site-packages/airflow/cli/commands/task_command.py", line 341, in _run_raw_task
    return ti._run_raw_task(
           ^^^^^^^^^^^^^^^^^
  File "/home/airflow/.local/lib/python3.12/site-packages/airflow/utils/session.py", line 97, in wrapper
    return func(*args, session=session, **kwargs)
           ^^^^^^^^^^^^^^^^^^^^^^^^^^^^^^^^^^^^^^
  File "/home/airflow/.local/lib/python3.12/site-packages/airflow/models/taskinstance.py", line 3006, in _run_raw_task
    return _run_raw_task(
           ^^^^^^^^^^^^^^
  File "/home/airflow/.local/lib/python3.12/site-packages/airflow/models/taskinstance.py", line 274, in _run_raw_task
    TaskInstance._execute_task_with_callbacks(
  File "/home/airflow/.local/lib/python3.12/site-packages/airflow/models/taskinstance.py", line 3161, in _execute_task_with_callbacks
    result = self._execute_task(context, task_orig)
             ^^^^^^^^^^^^^^^^^^^^^^^^^^^^^^^^^^^^^^
  File "/home/airflow/.local/lib/python3.12/site-packages/airflow/models/taskinstance.py", line 3185, in _execute_task
    return _execute_task(self, context, task_orig)
           ^^^^^^^^^^^^^^^^^^^^^^^^^^^^^^^^^^^^^^^
  File "/home/airflow/.local/lib/python3.12/site-packages/airflow/models/taskinstance.py", line 768, in _execute_task
    result = _execute_callable(context=context, **execute_callable_kwargs)
             ^^^^^^^^^^^^^^^^^^^^^^^^^^^^^^^^^^^^^^^^^^^^^^^^^^^^^^^^^^^^^
  File "/home/airflow/.local/lib/python3.12/site-packages/airflow/models/taskinstance.py", line 734, in _execute_callable
    return ExecutionCallableRunner(
           ^^^^^^^^^^^^^^^^^^^^^^^^
  File "/home/airflow/.local/lib/python3.12/site-packages/airflow/utils/operator_helpers.py", line 252, in run
    return self.func(*args, **kwargs)
           ^^^^^^^^^^^^^^^^^^^^^^^^^^
  File "/home/airflow/.local/lib/python3.12/site-packages/airflow/models/baseoperator.py", line 424, in wrapper
    return func(self, *args, **kwargs)
           ^^^^^^^^^^^^^^^^^^^^^^^^^^^
  File "/home/airflow/.local/lib/python3.12/site-packages/airflow/operators/python.py", line 238, in execute
    return_value = self.execute_callable()
                   ^^^^^^^^^^^^^^^^^^^^^^^
  File "/home/airflow/.local/lib/python3.12/site-packages/airflow/operators/python.py", line 256, in execute_callable
    return runner.run(*self.op_args, **self.op_kwargs)
           ^^^^^^^^^^^^^^^^^^^^^^^^^^^^^^^^^^^^^^^^^^^
  File "/home/airflow/.local/lib/python3.12/site-packages/airflow/utils/operator_helpers.py", line 252, in run
    return self.func(*args, **kwargs)
           ^^^^^^^^^^^^^^^^^^^^^^^^^^
  File "/opt/airflow/dags/scripts/download_data.py", line 11, in download_data
    os.makedirs(data_dir, exist_ok=True)
  File "<frozen os>", line 225, in makedirs
PermissionError: [Errno 13] Permission denied: '../Data'
[2025-04-01T10:44:37.361+0000] {local_task_job_runner.py:266} INFO - Task exited with return code 1
[2025-04-01T10:44:37.506+0000] {taskinstance.py:3901} INFO - 0 downstream tasks scheduled from follow-on schedule check
[2025-04-01T10:44:37.523+0000] {local_task_job_runner.py:245} INFO - ::endgroup::
[2025-04-01T11:32:03.323+0000] {local_task_job_runner.py:123} INFO - ::group::Pre task execution logs
[2025-04-01T11:32:03.494+0000] {taskinstance.py:2614} INFO - Dependencies all met for dep_context=non-requeueable deps ti=<TaskInstance: premier_league_ingestion.download_data_2019_20 scheduled__2025-03-23T00:00:00+00:00 [queued]>
[2025-04-01T11:32:03.559+0000] {taskinstance.py:2614} INFO - Dependencies all met for dep_context=requeueable deps ti=<TaskInstance: premier_league_ingestion.download_data_2019_20 scheduled__2025-03-23T00:00:00+00:00 [queued]>
[2025-04-01T11:32:03.577+0000] {taskinstance.py:2867} INFO - Starting attempt 2 of 2
[2025-04-01T11:32:03.650+0000] {taskinstance.py:2890} INFO - Executing <Task(PythonOperator): download_data_2019_20> on 2025-03-23 00:00:00+00:00
[2025-04-01T11:32:03.687+0000] {warnings.py:112} WARNING - /home/***/.local/lib/python3.12/site-packages/***/task/task_runner/standard_task_runner.py:70: DeprecationWarning: This process (pid=512) is multi-threaded, use of fork() may lead to deadlocks in the child.
  pid = os.fork()

[2025-04-01T11:32:03.693+0000] {standard_task_runner.py:72} INFO - Started process 521 to run task
[2025-04-01T11:32:03.704+0000] {standard_task_runner.py:104} INFO - Running: ['***', 'tasks', 'run', 'premier_league_ingestion', 'download_data_2019_20', 'scheduled__2025-03-23T00:00:00+00:00', '--job-id', '13', '--raw', '--subdir', 'DAGS_FOLDER/premier_league_dag.py', '--cfg-path', '/tmp/tmp6o7g8mui']
[2025-04-01T11:32:03.710+0000] {standard_task_runner.py:105} INFO - Job 13: Subtask download_data_2019_20
[2025-04-01T11:32:03.987+0000] {task_command.py:467} INFO - Running <TaskInstance: premier_league_ingestion.download_data_2019_20 scheduled__2025-03-23T00:00:00+00:00 [running]> on host 0366bde5a007
[2025-04-01T11:32:04.363+0000] {taskinstance.py:3134} INFO - Exporting env vars: AIRFLOW_CTX_DAG_OWNER='***' AIRFLOW_CTX_DAG_ID='premier_league_ingestion' AIRFLOW_CTX_TASK_ID='download_data_2019_20' AIRFLOW_CTX_EXECUTION_DATE='2025-03-23T00:00:00+00:00' AIRFLOW_CTX_TRY_NUMBER='2' AIRFLOW_CTX_DAG_RUN_ID='scheduled__2025-03-23T00:00:00+00:00'
[2025-04-01T11:32:04.365+0000] {taskinstance.py:732} INFO - ::endgroup::
[2025-04-01T11:32:04.435+0000] {taskinstance.py:3313} ERROR - Task failed with exception
Traceback (most recent call last):
  File "/home/airflow/.local/lib/python3.12/site-packages/airflow/models/taskinstance.py", line 768, in _execute_task
    result = _execute_callable(context=context, **execute_callable_kwargs)
             ^^^^^^^^^^^^^^^^^^^^^^^^^^^^^^^^^^^^^^^^^^^^^^^^^^^^^^^^^^^^^
  File "/home/airflow/.local/lib/python3.12/site-packages/airflow/models/taskinstance.py", line 734, in _execute_callable
    return ExecutionCallableRunner(
           ^^^^^^^^^^^^^^^^^^^^^^^^
  File "/home/airflow/.local/lib/python3.12/site-packages/airflow/utils/operator_helpers.py", line 252, in run
    return self.func(*args, **kwargs)
           ^^^^^^^^^^^^^^^^^^^^^^^^^^
  File "/home/airflow/.local/lib/python3.12/site-packages/airflow/models/baseoperator.py", line 424, in wrapper
    return func(self, *args, **kwargs)
           ^^^^^^^^^^^^^^^^^^^^^^^^^^^
  File "/home/airflow/.local/lib/python3.12/site-packages/airflow/operators/python.py", line 238, in execute
    return_value = self.execute_callable()
                   ^^^^^^^^^^^^^^^^^^^^^^^
  File "/home/airflow/.local/lib/python3.12/site-packages/airflow/operators/python.py", line 256, in execute_callable
    return runner.run(*self.op_args, **self.op_kwargs)
           ^^^^^^^^^^^^^^^^^^^^^^^^^^^^^^^^^^^^^^^^^^^
  File "/home/airflow/.local/lib/python3.12/site-packages/airflow/utils/operator_helpers.py", line 252, in run
    return self.func(*args, **kwargs)
           ^^^^^^^^^^^^^^^^^^^^^^^^^^
  File "/opt/airflow/dags/scripts/download_data.py", line 13, in download_data
    os.makedirs(data_dir, exist_ok=True)
  File "<frozen os>", line 225, in makedirs
PermissionError: [Errno 13] Permission denied: '../data'
[2025-04-01T11:32:04.465+0000] {taskinstance.py:1226} INFO - Marking task as FAILED. dag_id=premier_league_ingestion, task_id=download_data_2019_20, run_id=scheduled__2025-03-23T00:00:00+00:00, execution_date=20250323T000000, start_date=20250401T113203, end_date=20250401T113204
[2025-04-01T11:32:04.873+0000] {taskinstance.py:341} INFO - ::group::Post task execution logs
[2025-04-01T11:32:04.878+0000] {standard_task_runner.py:124} ERROR - Failed to execute job 13 for task download_data_2019_20 ([Errno 13] Permission denied: '../data'; 521)
Traceback (most recent call last):
  File "/home/airflow/.local/lib/python3.12/site-packages/airflow/task/task_runner/standard_task_runner.py", line 117, in _start_by_fork
    ret = args.func(args, dag=self.dag)
          ^^^^^^^^^^^^^^^^^^^^^^^^^^^^^
  File "/home/airflow/.local/lib/python3.12/site-packages/airflow/cli/cli_config.py", line 49, in command
    return func(*args, **kwargs)
           ^^^^^^^^^^^^^^^^^^^^^
  File "/home/airflow/.local/lib/python3.12/site-packages/airflow/utils/cli.py", line 116, in wrapper
    return f(*args, **kwargs)
           ^^^^^^^^^^^^^^^^^^
  File "/home/airflow/.local/lib/python3.12/site-packages/airflow/cli/commands/task_command.py", line 483, in task_run
    task_return_code = _run_task_by_selected_method(args, _dag, ti)
                       ^^^^^^^^^^^^^^^^^^^^^^^^^^^^^^^^^^^^^^^^^^^^
  File "/home/airflow/.local/lib/python3.12/site-packages/airflow/cli/commands/task_command.py", line 256, in _run_task_by_selected_method
    return _run_raw_task(args, ti)
           ^^^^^^^^^^^^^^^^^^^^^^^
  File "/home/airflow/.local/lib/python3.12/site-packages/airflow/cli/commands/task_command.py", line 341, in _run_raw_task
    return ti._run_raw_task(
           ^^^^^^^^^^^^^^^^^
  File "/home/airflow/.local/lib/python3.12/site-packages/airflow/utils/session.py", line 97, in wrapper
    return func(*args, session=session, **kwargs)
           ^^^^^^^^^^^^^^^^^^^^^^^^^^^^^^^^^^^^^^
  File "/home/airflow/.local/lib/python3.12/site-packages/airflow/models/taskinstance.py", line 3006, in _run_raw_task
    return _run_raw_task(
           ^^^^^^^^^^^^^^
  File "/home/airflow/.local/lib/python3.12/site-packages/airflow/models/taskinstance.py", line 274, in _run_raw_task
    TaskInstance._execute_task_with_callbacks(
  File "/home/airflow/.local/lib/python3.12/site-packages/airflow/models/taskinstance.py", line 3161, in _execute_task_with_callbacks
    result = self._execute_task(context, task_orig)
             ^^^^^^^^^^^^^^^^^^^^^^^^^^^^^^^^^^^^^^
  File "/home/airflow/.local/lib/python3.12/site-packages/airflow/models/taskinstance.py", line 3185, in _execute_task
    return _execute_task(self, context, task_orig)
           ^^^^^^^^^^^^^^^^^^^^^^^^^^^^^^^^^^^^^^^
  File "/home/airflow/.local/lib/python3.12/site-packages/airflow/models/taskinstance.py", line 768, in _execute_task
    result = _execute_callable(context=context, **execute_callable_kwargs)
             ^^^^^^^^^^^^^^^^^^^^^^^^^^^^^^^^^^^^^^^^^^^^^^^^^^^^^^^^^^^^^
  File "/home/airflow/.local/lib/python3.12/site-packages/airflow/models/taskinstance.py", line 734, in _execute_callable
    return ExecutionCallableRunner(
           ^^^^^^^^^^^^^^^^^^^^^^^^
  File "/home/airflow/.local/lib/python3.12/site-packages/airflow/utils/operator_helpers.py", line 252, in run
    return self.func(*args, **kwargs)
           ^^^^^^^^^^^^^^^^^^^^^^^^^^
  File "/home/airflow/.local/lib/python3.12/site-packages/airflow/models/baseoperator.py", line 424, in wrapper
    return func(self, *args, **kwargs)
           ^^^^^^^^^^^^^^^^^^^^^^^^^^^
  File "/home/airflow/.local/lib/python3.12/site-packages/airflow/operators/python.py", line 238, in execute
    return_value = self.execute_callable()
                   ^^^^^^^^^^^^^^^^^^^^^^^
  File "/home/airflow/.local/lib/python3.12/site-packages/airflow/operators/python.py", line 256, in execute_callable
    return runner.run(*self.op_args, **self.op_kwargs)
           ^^^^^^^^^^^^^^^^^^^^^^^^^^^^^^^^^^^^^^^^^^^
  File "/home/airflow/.local/lib/python3.12/site-packages/airflow/utils/operator_helpers.py", line 252, in run
    return self.func(*args, **kwargs)
           ^^^^^^^^^^^^^^^^^^^^^^^^^^
  File "/opt/airflow/dags/scripts/download_data.py", line 13, in download_data
    os.makedirs(data_dir, exist_ok=True)
  File "<frozen os>", line 225, in makedirs
PermissionError: [Errno 13] Permission denied: '../data'
[2025-04-01T11:32:04.970+0000] {local_task_job_runner.py:266} INFO - Task exited with return code 1
[2025-04-01T11:32:05.439+0000] {taskinstance.py:3901} INFO - 0 downstream tasks scheduled from follow-on schedule check
[2025-04-01T11:32:05.462+0000] {local_task_job_runner.py:245} INFO - ::endgroup::
