[2025-04-01T10:51:40.204+0000] {local_task_job_runner.py:123} INFO - ::group::Pre task execution logs
[2025-04-01T10:51:40.326+0000] {taskinstance.py:2614} INFO - Dependencies all met for dep_context=non-requeueable deps ti=<TaskInstance: premier_league_ingestion.download_data_2019_20 scheduled__2025-03-23T00:00:00+00:00 [queued]>
[2025-04-01T10:51:40.350+0000] {taskinstance.py:2614} INFO - Dependencies all met for dep_context=requeueable deps ti=<TaskInstance: premier_league_ingestion.download_data_2019_20 scheduled__2025-03-23T00:00:00+00:00 [queued]>
[2025-04-01T10:51:40.351+0000] {taskinstance.py:2867} INFO - Starting attempt 5 of 6
[2025-04-01T10:51:40.389+0000] {taskinstance.py:2890} INFO - Executing <Task(PythonOperator): download_data_2019_20> on 2025-03-23 00:00:00+00:00
[2025-04-01T10:51:40.415+0000] {warnings.py:112} WARNING - /home/***/.local/lib/python3.12/site-packages/***/task/task_runner/standard_task_runner.py:70: DeprecationWarning: This process (pid=360) is multi-threaded, use of fork() may lead to deadlocks in the child.
  pid = os.fork()

[2025-04-01T10:51:40.430+0000] {standard_task_runner.py:72} INFO - Started process 362 to run task
[2025-04-01T10:51:40.448+0000] {standard_task_runner.py:104} INFO - Running: ['***', 'tasks', 'run', 'premier_league_ingestion', 'download_data_2019_20', 'scheduled__2025-03-23T00:00:00+00:00', '--job-id', '18', '--raw', '--subdir', 'DAGS_FOLDER/premier_league_dag.py', '--cfg-path', '/tmp/tmp1vxztfxy']
[2025-04-01T10:51:40.466+0000] {standard_task_runner.py:105} INFO - Job 18: Subtask download_data_2019_20
[2025-04-01T10:51:40.673+0000] {task_command.py:467} INFO - Running <TaskInstance: premier_league_ingestion.download_data_2019_20 scheduled__2025-03-23T00:00:00+00:00 [running]> on host 6cd6fb1a2334
[2025-04-01T10:51:40.866+0000] {taskinstance.py:3134} INFO - Exporting env vars: AIRFLOW_CTX_DAG_OWNER='***' AIRFLOW_CTX_DAG_ID='premier_league_ingestion' AIRFLOW_CTX_TASK_ID='download_data_2019_20' AIRFLOW_CTX_EXECUTION_DATE='2025-03-23T00:00:00+00:00' AIRFLOW_CTX_TRY_NUMBER='5' AIRFLOW_CTX_DAG_RUN_ID='scheduled__2025-03-23T00:00:00+00:00'
[2025-04-01T10:51:40.868+0000] {taskinstance.py:732} INFO - ::endgroup::
[2025-04-01T10:51:40.899+0000] {taskinstance.py:3313} ERROR - Task failed with exception
Traceback (most recent call last):
  File "/home/airflow/.local/lib/python3.12/site-packages/selenium/webdriver/common/driver_finder.py", line 64, in _binary_paths
    raise ValueError(f"The path is not a valid file: {path}")
ValueError: The path is not a valid file: /home/Data_Professional/PycharmProjects/DE_Zoomcamp_Capstone_Project/chromedriver-linux64/chromedriver

The above exception was the direct cause of the following exception:

Traceback (most recent call last):
  File "/home/airflow/.local/lib/python3.12/site-packages/airflow/models/taskinstance.py", line 768, in _execute_task
    result = _execute_callable(context=context, **execute_callable_kwargs)
             ^^^^^^^^^^^^^^^^^^^^^^^^^^^^^^^^^^^^^^^^^^^^^^^^^^^^^^^^^^^^^
  File "/home/airflow/.local/lib/python3.12/site-packages/airflow/models/taskinstance.py", line 734, in _execute_callable
    return ExecutionCallableRunner(
           ^^^^^^^^^^^^^^^^^^^^^^^^
  File "/home/airflow/.local/lib/python3.12/site-packages/airflow/utils/operator_helpers.py", line 252, in run
    return self.func(*args, **kwargs)
           ^^^^^^^^^^^^^^^^^^^^^^^^^^
  File "/home/airflow/.local/lib/python3.12/site-packages/airflow/models/baseoperator.py", line 424, in wrapper
    return func(self, *args, **kwargs)
           ^^^^^^^^^^^^^^^^^^^^^^^^^^^
  File "/home/airflow/.local/lib/python3.12/site-packages/airflow/operators/python.py", line 238, in execute
    return_value = self.execute_callable()
                   ^^^^^^^^^^^^^^^^^^^^^^^
  File "/home/airflow/.local/lib/python3.12/site-packages/airflow/operators/python.py", line 256, in execute_callable
    return runner.run(*self.op_args, **self.op_kwargs)
           ^^^^^^^^^^^^^^^^^^^^^^^^^^^^^^^^^^^^^^^^^^^
  File "/home/airflow/.local/lib/python3.12/site-packages/airflow/utils/operator_helpers.py", line 252, in run
    return self.func(*args, **kwargs)
           ^^^^^^^^^^^^^^^^^^^^^^^^^^
  File "/opt/airflow/dags/scripts/download_data.py", line 16, in download_data
    crawler = Crawler(season)
              ^^^^^^^^^^^^^^^
  File "/opt/airflow/dags/scripts/crawler.py", line 21, in __init__
    self.driver = self._setup_driver()
                  ^^^^^^^^^^^^^^^^^^^^
  File "/opt/airflow/dags/scripts/crawler.py", line 28, in _setup_driver
    driver = webdriver.Chrome(service=service)
             ^^^^^^^^^^^^^^^^^^^^^^^^^^^^^^^^^
  File "/home/airflow/.local/lib/python3.12/site-packages/selenium/webdriver/chrome/webdriver.py", line 45, in __init__
    super().__init__(
  File "/home/airflow/.local/lib/python3.12/site-packages/selenium/webdriver/chromium/webdriver.py", line 50, in __init__
    if finder.get_browser_path():
       ^^^^^^^^^^^^^^^^^^^^^^^^^
  File "/home/airflow/.local/lib/python3.12/site-packages/selenium/webdriver/common/driver_finder.py", line 47, in get_browser_path
    return self._binary_paths()["browser_path"]
           ^^^^^^^^^^^^^^^^^^^^
  File "/home/airflow/.local/lib/python3.12/site-packages/selenium/webdriver/common/driver_finder.py", line 78, in _binary_paths
    raise NoSuchDriverException(msg) from err
selenium.common.exceptions.NoSuchDriverException: Message: Unable to obtain driver for chrome; For documentation on this error, please visit: https://www.selenium.dev/documentation/webdriver/troubleshooting/errors/driver_location

[2025-04-01T10:51:40.924+0000] {taskinstance.py:1226} INFO - Marking task as UP_FOR_RETRY. dag_id=premier_league_ingestion, task_id=download_data_2019_20, run_id=scheduled__2025-03-23T00:00:00+00:00, execution_date=20250323T000000, start_date=20250401T105140, end_date=20250401T105140
[2025-04-01T10:51:41.020+0000] {taskinstance.py:341} INFO - ::group::Post task execution logs
[2025-04-01T10:51:41.021+0000] {standard_task_runner.py:124} ERROR - Failed to execute job 18 for task download_data_2019_20 (Message: Unable to obtain driver for chrome; For documentation on this error, please visit: https://www.selenium.dev/documentation/webdriver/troubleshooting/errors/driver_location
; 362)
Traceback (most recent call last):
  File "/home/airflow/.local/lib/python3.12/site-packages/selenium/webdriver/common/driver_finder.py", line 64, in _binary_paths
    raise ValueError(f"The path is not a valid file: {path}")
ValueError: The path is not a valid file: /home/Data_Professional/PycharmProjects/DE_Zoomcamp_Capstone_Project/chromedriver-linux64/chromedriver

The above exception was the direct cause of the following exception:

Traceback (most recent call last):
  File "/home/airflow/.local/lib/python3.12/site-packages/airflow/task/task_runner/standard_task_runner.py", line 117, in _start_by_fork
    ret = args.func(args, dag=self.dag)
          ^^^^^^^^^^^^^^^^^^^^^^^^^^^^^
  File "/home/airflow/.local/lib/python3.12/site-packages/airflow/cli/cli_config.py", line 49, in command
    return func(*args, **kwargs)
           ^^^^^^^^^^^^^^^^^^^^^
  File "/home/airflow/.local/lib/python3.12/site-packages/airflow/utils/cli.py", line 116, in wrapper
    return f(*args, **kwargs)
           ^^^^^^^^^^^^^^^^^^
  File "/home/airflow/.local/lib/python3.12/site-packages/airflow/cli/commands/task_command.py", line 483, in task_run
    task_return_code = _run_task_by_selected_method(args, _dag, ti)
                       ^^^^^^^^^^^^^^^^^^^^^^^^^^^^^^^^^^^^^^^^^^^^
  File "/home/airflow/.local/lib/python3.12/site-packages/airflow/cli/commands/task_command.py", line 256, in _run_task_by_selected_method
    return _run_raw_task(args, ti)
           ^^^^^^^^^^^^^^^^^^^^^^^
  File "/home/airflow/.local/lib/python3.12/site-packages/airflow/cli/commands/task_command.py", line 341, in _run_raw_task
    return ti._run_raw_task(
           ^^^^^^^^^^^^^^^^^
  File "/home/airflow/.local/lib/python3.12/site-packages/airflow/utils/session.py", line 97, in wrapper
    return func(*args, session=session, **kwargs)
           ^^^^^^^^^^^^^^^^^^^^^^^^^^^^^^^^^^^^^^
  File "/home/airflow/.local/lib/python3.12/site-packages/airflow/models/taskinstance.py", line 3006, in _run_raw_task
    return _run_raw_task(
           ^^^^^^^^^^^^^^
  File "/home/airflow/.local/lib/python3.12/site-packages/airflow/models/taskinstance.py", line 274, in _run_raw_task
    TaskInstance._execute_task_with_callbacks(
  File "/home/airflow/.local/lib/python3.12/site-packages/airflow/models/taskinstance.py", line 3161, in _execute_task_with_callbacks
    result = self._execute_task(context, task_orig)
             ^^^^^^^^^^^^^^^^^^^^^^^^^^^^^^^^^^^^^^
  File "/home/airflow/.local/lib/python3.12/site-packages/airflow/models/taskinstance.py", line 3185, in _execute_task
    return _execute_task(self, context, task_orig)
           ^^^^^^^^^^^^^^^^^^^^^^^^^^^^^^^^^^^^^^^
  File "/home/airflow/.local/lib/python3.12/site-packages/airflow/models/taskinstance.py", line 768, in _execute_task
    result = _execute_callable(context=context, **execute_callable_kwargs)
             ^^^^^^^^^^^^^^^^^^^^^^^^^^^^^^^^^^^^^^^^^^^^^^^^^^^^^^^^^^^^^
  File "/home/airflow/.local/lib/python3.12/site-packages/airflow/models/taskinstance.py", line 734, in _execute_callable
    return ExecutionCallableRunner(
           ^^^^^^^^^^^^^^^^^^^^^^^^
  File "/home/airflow/.local/lib/python3.12/site-packages/airflow/utils/operator_helpers.py", line 252, in run
    return self.func(*args, **kwargs)
           ^^^^^^^^^^^^^^^^^^^^^^^^^^
  File "/home/airflow/.local/lib/python3.12/site-packages/airflow/models/baseoperator.py", line 424, in wrapper
    return func(self, *args, **kwargs)
           ^^^^^^^^^^^^^^^^^^^^^^^^^^^
  File "/home/airflow/.local/lib/python3.12/site-packages/airflow/operators/python.py", line 238, in execute
    return_value = self.execute_callable()
                   ^^^^^^^^^^^^^^^^^^^^^^^
  File "/home/airflow/.local/lib/python3.12/site-packages/airflow/operators/python.py", line 256, in execute_callable
    return runner.run(*self.op_args, **self.op_kwargs)
           ^^^^^^^^^^^^^^^^^^^^^^^^^^^^^^^^^^^^^^^^^^^
  File "/home/airflow/.local/lib/python3.12/site-packages/airflow/utils/operator_helpers.py", line 252, in run
    return self.func(*args, **kwargs)
           ^^^^^^^^^^^^^^^^^^^^^^^^^^
  File "/opt/airflow/dags/scripts/download_data.py", line 16, in download_data
    crawler = Crawler(season)
              ^^^^^^^^^^^^^^^
  File "/opt/airflow/dags/scripts/crawler.py", line 21, in __init__
    self.driver = self._setup_driver()
                  ^^^^^^^^^^^^^^^^^^^^
  File "/opt/airflow/dags/scripts/crawler.py", line 28, in _setup_driver
    driver = webdriver.Chrome(service=service)
             ^^^^^^^^^^^^^^^^^^^^^^^^^^^^^^^^^
  File "/home/airflow/.local/lib/python3.12/site-packages/selenium/webdriver/chrome/webdriver.py", line 45, in __init__
    super().__init__(
  File "/home/airflow/.local/lib/python3.12/site-packages/selenium/webdriver/chromium/webdriver.py", line 50, in __init__
    if finder.get_browser_path():
       ^^^^^^^^^^^^^^^^^^^^^^^^^
  File "/home/airflow/.local/lib/python3.12/site-packages/selenium/webdriver/common/driver_finder.py", line 47, in get_browser_path
    return self._binary_paths()["browser_path"]
           ^^^^^^^^^^^^^^^^^^^^
  File "/home/airflow/.local/lib/python3.12/site-packages/selenium/webdriver/common/driver_finder.py", line 78, in _binary_paths
    raise NoSuchDriverException(msg) from err
selenium.common.exceptions.NoSuchDriverException: Message: Unable to obtain driver for chrome; For documentation on this error, please visit: https://www.selenium.dev/documentation/webdriver/troubleshooting/errors/driver_location

[2025-04-01T10:51:41.046+0000] {local_task_job_runner.py:266} INFO - Task exited with return code 1
[2025-04-01T10:51:41.086+0000] {taskinstance.py:3901} INFO - 0 downstream tasks scheduled from follow-on schedule check
[2025-04-01T10:51:41.088+0000] {local_task_job_runner.py:245} INFO - ::endgroup::
[2025-04-01T11:41:55.048+0000] {local_task_job_runner.py:123} INFO - ::group::Pre task execution logs
[2025-04-01T11:41:55.082+0000] {taskinstance.py:2614} INFO - Dependencies all met for dep_context=non-requeueable deps ti=<TaskInstance: premier_league_ingestion.download_data_2019_20 scheduled__2025-03-23T00:00:00+00:00 [queued]>
[2025-04-01T11:41:55.101+0000] {taskinstance.py:2614} INFO - Dependencies all met for dep_context=requeueable deps ti=<TaskInstance: premier_league_ingestion.download_data_2019_20 scheduled__2025-03-23T00:00:00+00:00 [queued]>
[2025-04-01T11:41:55.103+0000] {taskinstance.py:2867} INFO - Starting attempt 5 of 6
[2025-04-01T11:41:55.128+0000] {taskinstance.py:2890} INFO - Executing <Task(PythonOperator): download_data_2019_20> on 2025-03-23 00:00:00+00:00
[2025-04-01T11:41:55.145+0000] {warnings.py:112} WARNING - /home/***/.local/lib/python3.12/site-packages/***/task/task_runner/standard_task_runner.py:70: DeprecationWarning: This process (pid=677) is multi-threaded, use of fork() may lead to deadlocks in the child.
  pid = os.fork()

[2025-04-01T11:41:55.149+0000] {standard_task_runner.py:72} INFO - Started process 679 to run task
[2025-04-01T11:41:55.151+0000] {standard_task_runner.py:104} INFO - Running: ['***', 'tasks', 'run', 'premier_league_ingestion', 'download_data_2019_20', 'scheduled__2025-03-23T00:00:00+00:00', '--job-id', '25', '--raw', '--subdir', 'DAGS_FOLDER/premier_league_dag.py', '--cfg-path', '/tmp/tmpwh8roihq']
[2025-04-01T11:41:55.163+0000] {standard_task_runner.py:105} INFO - Job 25: Subtask download_data_2019_20
[2025-04-01T11:41:55.282+0000] {task_command.py:467} INFO - Running <TaskInstance: premier_league_ingestion.download_data_2019_20 scheduled__2025-03-23T00:00:00+00:00 [running]> on host 0366bde5a007
[2025-04-01T11:41:55.409+0000] {taskinstance.py:3134} INFO - Exporting env vars: AIRFLOW_CTX_DAG_OWNER='***' AIRFLOW_CTX_DAG_ID='premier_league_ingestion' AIRFLOW_CTX_TASK_ID='download_data_2019_20' AIRFLOW_CTX_EXECUTION_DATE='2025-03-23T00:00:00+00:00' AIRFLOW_CTX_TRY_NUMBER='5' AIRFLOW_CTX_DAG_RUN_ID='scheduled__2025-03-23T00:00:00+00:00'
[2025-04-01T11:41:55.413+0000] {taskinstance.py:732} INFO - ::endgroup::
[2025-04-01T11:41:55.440+0000] {taskinstance.py:3313} ERROR - Task failed with exception
Traceback (most recent call last):
  File "/home/airflow/.local/lib/python3.12/site-packages/selenium/webdriver/common/driver_finder.py", line 64, in _binary_paths
    raise ValueError(f"The path is not a valid file: {path}")
ValueError: The path is not a valid file: ../chromedriver-linux64/chromedriver

The above exception was the direct cause of the following exception:

Traceback (most recent call last):
  File "/home/airflow/.local/lib/python3.12/site-packages/airflow/models/taskinstance.py", line 768, in _execute_task
    result = _execute_callable(context=context, **execute_callable_kwargs)
             ^^^^^^^^^^^^^^^^^^^^^^^^^^^^^^^^^^^^^^^^^^^^^^^^^^^^^^^^^^^^^
  File "/home/airflow/.local/lib/python3.12/site-packages/airflow/models/taskinstance.py", line 734, in _execute_callable
    return ExecutionCallableRunner(
           ^^^^^^^^^^^^^^^^^^^^^^^^
  File "/home/airflow/.local/lib/python3.12/site-packages/airflow/utils/operator_helpers.py", line 252, in run
    return self.func(*args, **kwargs)
           ^^^^^^^^^^^^^^^^^^^^^^^^^^
  File "/home/airflow/.local/lib/python3.12/site-packages/airflow/models/baseoperator.py", line 424, in wrapper
    return func(self, *args, **kwargs)
           ^^^^^^^^^^^^^^^^^^^^^^^^^^^
  File "/home/airflow/.local/lib/python3.12/site-packages/airflow/operators/python.py", line 238, in execute
    return_value = self.execute_callable()
                   ^^^^^^^^^^^^^^^^^^^^^^^
  File "/home/airflow/.local/lib/python3.12/site-packages/airflow/operators/python.py", line 256, in execute_callable
    return runner.run(*self.op_args, **self.op_kwargs)
           ^^^^^^^^^^^^^^^^^^^^^^^^^^^^^^^^^^^^^^^^^^^
  File "/home/airflow/.local/lib/python3.12/site-packages/airflow/utils/operator_helpers.py", line 252, in run
    return self.func(*args, **kwargs)
           ^^^^^^^^^^^^^^^^^^^^^^^^^^
  File "/opt/airflow/dags/scripts/download_data.py", line 17, in download_data
    crawler = Crawler(season)
              ^^^^^^^^^^^^^^^
  File "/opt/airflow/dags/scripts/crawler.py", line 21, in __init__
    self.driver = self._setup_driver()
                  ^^^^^^^^^^^^^^^^^^^^
  File "/opt/airflow/dags/scripts/crawler.py", line 28, in _setup_driver
    driver = webdriver.Chrome(service=service)
             ^^^^^^^^^^^^^^^^^^^^^^^^^^^^^^^^^
  File "/home/airflow/.local/lib/python3.12/site-packages/selenium/webdriver/chrome/webdriver.py", line 45, in __init__
    super().__init__(
  File "/home/airflow/.local/lib/python3.12/site-packages/selenium/webdriver/chromium/webdriver.py", line 50, in __init__
    if finder.get_browser_path():
       ^^^^^^^^^^^^^^^^^^^^^^^^^
  File "/home/airflow/.local/lib/python3.12/site-packages/selenium/webdriver/common/driver_finder.py", line 47, in get_browser_path
    return self._binary_paths()["browser_path"]
           ^^^^^^^^^^^^^^^^^^^^
  File "/home/airflow/.local/lib/python3.12/site-packages/selenium/webdriver/common/driver_finder.py", line 78, in _binary_paths
    raise NoSuchDriverException(msg) from err
selenium.common.exceptions.NoSuchDriverException: Message: Unable to obtain driver for chrome; For documentation on this error, please visit: https://www.selenium.dev/documentation/webdriver/troubleshooting/errors/driver_location

[2025-04-01T11:41:55.466+0000] {taskinstance.py:1226} INFO - Marking task as UP_FOR_RETRY. dag_id=premier_league_ingestion, task_id=download_data_2019_20, run_id=scheduled__2025-03-23T00:00:00+00:00, execution_date=20250323T000000, start_date=20250401T114155, end_date=20250401T114155
[2025-04-01T11:41:55.517+0000] {taskinstance.py:341} INFO - ::group::Post task execution logs
[2025-04-01T11:41:55.519+0000] {standard_task_runner.py:124} ERROR - Failed to execute job 25 for task download_data_2019_20 (Message: Unable to obtain driver for chrome; For documentation on this error, please visit: https://www.selenium.dev/documentation/webdriver/troubleshooting/errors/driver_location
; 679)
Traceback (most recent call last):
  File "/home/airflow/.local/lib/python3.12/site-packages/selenium/webdriver/common/driver_finder.py", line 64, in _binary_paths
    raise ValueError(f"The path is not a valid file: {path}")
ValueError: The path is not a valid file: ../chromedriver-linux64/chromedriver

The above exception was the direct cause of the following exception:

Traceback (most recent call last):
  File "/home/airflow/.local/lib/python3.12/site-packages/airflow/task/task_runner/standard_task_runner.py", line 117, in _start_by_fork
    ret = args.func(args, dag=self.dag)
          ^^^^^^^^^^^^^^^^^^^^^^^^^^^^^
  File "/home/airflow/.local/lib/python3.12/site-packages/airflow/cli/cli_config.py", line 49, in command
    return func(*args, **kwargs)
           ^^^^^^^^^^^^^^^^^^^^^
  File "/home/airflow/.local/lib/python3.12/site-packages/airflow/utils/cli.py", line 116, in wrapper
    return f(*args, **kwargs)
           ^^^^^^^^^^^^^^^^^^
  File "/home/airflow/.local/lib/python3.12/site-packages/airflow/cli/commands/task_command.py", line 483, in task_run
    task_return_code = _run_task_by_selected_method(args, _dag, ti)
                       ^^^^^^^^^^^^^^^^^^^^^^^^^^^^^^^^^^^^^^^^^^^^
  File "/home/airflow/.local/lib/python3.12/site-packages/airflow/cli/commands/task_command.py", line 256, in _run_task_by_selected_method
    return _run_raw_task(args, ti)
           ^^^^^^^^^^^^^^^^^^^^^^^
  File "/home/airflow/.local/lib/python3.12/site-packages/airflow/cli/commands/task_command.py", line 341, in _run_raw_task
    return ti._run_raw_task(
           ^^^^^^^^^^^^^^^^^
  File "/home/airflow/.local/lib/python3.12/site-packages/airflow/utils/session.py", line 97, in wrapper
    return func(*args, session=session, **kwargs)
           ^^^^^^^^^^^^^^^^^^^^^^^^^^^^^^^^^^^^^^
  File "/home/airflow/.local/lib/python3.12/site-packages/airflow/models/taskinstance.py", line 3006, in _run_raw_task
    return _run_raw_task(
           ^^^^^^^^^^^^^^
  File "/home/airflow/.local/lib/python3.12/site-packages/airflow/models/taskinstance.py", line 274, in _run_raw_task
    TaskInstance._execute_task_with_callbacks(
  File "/home/airflow/.local/lib/python3.12/site-packages/airflow/models/taskinstance.py", line 3161, in _execute_task_with_callbacks
    result = self._execute_task(context, task_orig)
             ^^^^^^^^^^^^^^^^^^^^^^^^^^^^^^^^^^^^^^
  File "/home/airflow/.local/lib/python3.12/site-packages/airflow/models/taskinstance.py", line 3185, in _execute_task
    return _execute_task(self, context, task_orig)
           ^^^^^^^^^^^^^^^^^^^^^^^^^^^^^^^^^^^^^^^
  File "/home/airflow/.local/lib/python3.12/site-packages/airflow/models/taskinstance.py", line 768, in _execute_task
    result = _execute_callable(context=context, **execute_callable_kwargs)
             ^^^^^^^^^^^^^^^^^^^^^^^^^^^^^^^^^^^^^^^^^^^^^^^^^^^^^^^^^^^^^
  File "/home/airflow/.local/lib/python3.12/site-packages/airflow/models/taskinstance.py", line 734, in _execute_callable
    return ExecutionCallableRunner(
           ^^^^^^^^^^^^^^^^^^^^^^^^
  File "/home/airflow/.local/lib/python3.12/site-packages/airflow/utils/operator_helpers.py", line 252, in run
    return self.func(*args, **kwargs)
           ^^^^^^^^^^^^^^^^^^^^^^^^^^
  File "/home/airflow/.local/lib/python3.12/site-packages/airflow/models/baseoperator.py", line 424, in wrapper
    return func(self, *args, **kwargs)
           ^^^^^^^^^^^^^^^^^^^^^^^^^^^
  File "/home/airflow/.local/lib/python3.12/site-packages/airflow/operators/python.py", line 238, in execute
    return_value = self.execute_callable()
                   ^^^^^^^^^^^^^^^^^^^^^^^
  File "/home/airflow/.local/lib/python3.12/site-packages/airflow/operators/python.py", line 256, in execute_callable
    return runner.run(*self.op_args, **self.op_kwargs)
           ^^^^^^^^^^^^^^^^^^^^^^^^^^^^^^^^^^^^^^^^^^^
  File "/home/airflow/.local/lib/python3.12/site-packages/airflow/utils/operator_helpers.py", line 252, in run
    return self.func(*args, **kwargs)
           ^^^^^^^^^^^^^^^^^^^^^^^^^^
  File "/opt/airflow/dags/scripts/download_data.py", line 17, in download_data
    crawler = Crawler(season)
              ^^^^^^^^^^^^^^^
  File "/opt/airflow/dags/scripts/crawler.py", line 21, in __init__
    self.driver = self._setup_driver()
                  ^^^^^^^^^^^^^^^^^^^^
  File "/opt/airflow/dags/scripts/crawler.py", line 28, in _setup_driver
    driver = webdriver.Chrome(service=service)
             ^^^^^^^^^^^^^^^^^^^^^^^^^^^^^^^^^
  File "/home/airflow/.local/lib/python3.12/site-packages/selenium/webdriver/chrome/webdriver.py", line 45, in __init__
    super().__init__(
  File "/home/airflow/.local/lib/python3.12/site-packages/selenium/webdriver/chromium/webdriver.py", line 50, in __init__
    if finder.get_browser_path():
       ^^^^^^^^^^^^^^^^^^^^^^^^^
  File "/home/airflow/.local/lib/python3.12/site-packages/selenium/webdriver/common/driver_finder.py", line 47, in get_browser_path
    return self._binary_paths()["browser_path"]
           ^^^^^^^^^^^^^^^^^^^^
  File "/home/airflow/.local/lib/python3.12/site-packages/selenium/webdriver/common/driver_finder.py", line 78, in _binary_paths
    raise NoSuchDriverException(msg) from err
selenium.common.exceptions.NoSuchDriverException: Message: Unable to obtain driver for chrome; For documentation on this error, please visit: https://www.selenium.dev/documentation/webdriver/troubleshooting/errors/driver_location

[2025-04-01T11:41:55.582+0000] {local_task_job_runner.py:266} INFO - Task exited with return code 1
[2025-04-01T11:41:55.612+0000] {taskinstance.py:3901} INFO - 0 downstream tasks scheduled from follow-on schedule check
[2025-04-01T11:41:55.616+0000] {local_task_job_runner.py:245} INFO - ::endgroup::
